Workbook
Name mois: Feuil4!#REF!
Name mois: Feuil4!#REF!
Name mois: Feuil4!#REF!
Name mois: Feuil4!#REF!
Name mois_bon2: Feuil4!$E$1:$E$100
Name mois_modif: Feuil4!$E$4:$E$32
Name nature_credit: [1]tresorerie!$P$8:$P$13
Name nature_debit: [1]tresorerie!$S$8:$S$13
Name secteur: Feuil4!$A$1:$A$4

Sheet fond_dispo_rep_interet
A1: N° | B1: Nom épargnant | C1: 44470 | D1: 44501 | E1: 44531 | F1: 44562 | G1: 44593 | H1: 44621 | I1: 44652 | J1: 44682 | K1: 44713 | L1: 44743 | M1: 44774 | N1: 44805 | O1: 44835 | P1: 44866 | Q1: 44896 | R1: 44927 | S1: 44958 | T1: 44986 | U1: 45017 | V1: 45047 | W1: 45078 | X1: 45108
A2: 1 | B2: BOUSSEKO Narcisse | C2: 24286.429 | E2: 5714.2857
A3: 2 | B3: DONGMO Clémence | C3: 8095.4762 | E3: 1904.7619
A4: 3 | B4: DONTSOP Jackson | C4: 256191 | D4: 61667 | E4: 65476.524
A5: 4 | B5: IFOU Sylvia | C5: 0 | E5: 0
A6: 5 | B6: KUITCHE Chevalier de Dieu | C6: 56668.333 | E6: 13333.333
A7: 6 | B7: LELE SIAKA Hernandez | C7: 0 | D7: 125000 | E7: 0
A8: 7 | B8: MOMIE Emilie | C8: 16190.952 | E8: 3809.5238
A9: 8 | B9: MONTE Valdese | C9: 8095.4762 | E9: 1904.7619
A10: 9 | B10: NOUTSA Eugène | C10: 32381.905 | E10: 7619.0476
A11: 10 | B11: SONGOU Sainclaire | C11: 72859.286 | E11: 17142.857
A12: 11 | B12: TAKOULEU Richardson | C12: 72859.286 | E12: 17142.857
A13: 12 | B13: TCHIOFO Appolinie | C13: 72859.286 | E13: 17142.857
A14: 13 | B14: TCHIOFO Fidélia | C14: 56668.333 | D14: 70000 | E14: 13333.333
A15: 14 | B15: TCHIOFO Paulin | C15: 64763.81 | E15: 15238.095
A16: 15 | B16: TCHIOFO Rodine | C16: 72859.286 | E16: 17142.857
A17: 16 | B17: TCHIOFO Sorelle | C17: 64763.81 | E17: 15238.095
A18: 17 | B18: TITNKHEU Moïse | C18: 72859.286 | E18: 17142.857
A19: 18 | B19: WANGUN Parfait | C19: 72859.286 | E19: 17142.857
A20: 19 | B20: YOUDOM Nadine | C20: 64763.81 | E20: 15238.095
A21: 20 | B21: DAGOBERT | C21: 40000
A22: 21 | B22: DJEUNOU Donna | C22: 120000
A31: Total | C31: =SUM(C2:C30) -> 1250025 | D31: =SUM(D2:D30) -> 256667 | E31: =SUM(E2:E30) -> 261667 | F31: =SUM(F2:F30) -> 0 | G31: =SUM(G2:G30) -> 0 | H31: =SUM(H2:H30) -> 0 | I31: =SUM(I2:I30) -> 0 | J31: =SUM(J2:J30) -> 0 | ... X31: =SUM(X2:X30) -> 0

Sheet epargne_mensuelle_ancien
A1: N° | B1: Nom épargnant | C1: 44470 | D1: 44501 | E1: 44531 | F1: 44562 | G1: 44593 | H1: 44621 | I1: 44652 | J1: 44682 | K1: 44713 | L1: 44743 | M1: 44774 | N1: 44805 | O1: 44835 | P1: 44866 | Q1: 44896 | R1: 44927 | S1: 44958 | T1: 44986 | U1: 45017 | V1: 45047 | W1: 45078 | X1: 45108
A2: 1 | B2: BOUSSEKO Narcisse | C2: 24286.429 | E2: 5714.2857 | F2: 13685.714
A3: 2 | B3: DONGMO Clémence | C3: 8095.4762 | E3: 1904.7619 | F3: 4561.9048
A4: 3 | B4: DONTSOP Jackson | C4: 256191 | D4: 61667 | E4: 65476.524 | F4: 69611
A5: 4 | B5: IFOU Sylvia | C5: 0 | E5: 0 | F5: 0
A6: 5 | B6: KUITCHE Chevalier de Dieu | C6: 56668.333 | E6: 13333.333 | F6: 31933.333
A7: 6 | B7: LELE SIAKA Hernandez | C7: 0 | D7: 125000 | E7: 0 | F7: 0
A8: 7 | B8: MOMIE Emilie | C8: 16190.952 | E8: 3809.5238 | F8: 9123.8095
A9: 8 | B9: MONTE Valdese | C9: 8095.4762 | E9: 1904.7619 | F9: 4561.9048
A10: 9 | B10: NOUTSA Eugène | C10: 32381.905 | E10: 7619.0476 | F10: 18247.619
A11: 10 | B11: SONGOU Sainclaire | C11: 72859.286 | E11: 17142.857 | F11: 41057.143
A12: 11 | B12: TAKOULEU Richardson | C12: 72859.286 | E12: 17142.857 | F12: 41057.143
A13: 12 | B13: TCHIOFO Appolinie | C13: 72859.286 | E13: 17142.857 | F13: 41057.143
A14: 13 | B14: TCHIOFO Fidélia | C14: 56668.333 | D14: 70000 | E14: 13333.333 | F14: 31933.333
A15: 14 | B15: TCHIOFO Paulin | C15: 64763.81 | E15: 15238.095 | F15: 36495.238
A16: 15 | B16: TCHIOFO Rodine | C16: 72859.286 | E16: 17142.857 | F16: 71057.143
A17: 16 | B17: TCHIOFO Sorelle | C17: 64763.81 | E17: 15238.095 | F17: 36495.238
A18: 17 | B18: TITNKHEU Moïse | C18: 72859.286 | E18: 17142.857 | F18: 41057.143
A19: 18 | B19: WANGUN Parfait | C19: 72859.286 | E19: 17142.857 | F19: 41057.143
A20: 19 | B20: YOUDOM Nadine | C20: 64763.81 | E20: 15238.095 | F20: 36495.238
A21: 20 | B21: DAGOBERT | C21: 40000
A22: 21 | B22: DJEUNOU Donna | C22: 120000
A31: Total | C31: =SUM(C2:C30) -> 1250025 | D31: =SUM(D2:D30) -> 256667 | E31: =SUM(E2:E30) -> 261667 | F31: =SUM(F2:F30) -> 569487.19 | G31: =SUM(G2:G30) -> 0 | H31: =SUM(H2:H30) -> 0 | I31: =SUM(I2:I30) -> 0 | J31: =SUM(J2:J30) -> 0 | ... X31: =SUM(X2:X30) -> 0

Sheet epargne_mensuelle_reelle
A1: N° | B1: Nom épargnant | C1: 44470 | D1: 44501 | E1: 44531 | F1: 44562 | G1: 44593 | H1: 44621 | I1: 44652 | J1: 44682 | K1: 44713 | L1: 44743 | M1: 44774 | N1: 44805 | O1: 44835 | P1: 44866 | Q1: 44896 | R1: 44927 | S1: 44958 | T1: 44986 | U1: 45017 | V1: 45047 | W1: 45078 | X1: 45108
A2: 1 | B2: BOUSSEKO Narcisse
A3: 2 | B3: DONGMO Clémence
A4: 3 | B4: DONTSOP Jackson | C4: 240000 | D4: 61667 | E4: 61667 | F4: 60487
A5: 4 | B5: IFOU Sylvia
A6: 5 | B6: KUITCHE Chevalier de Dieu
A7: 6 | B7: LELE SIAKA Hernandez | D7: 125000
A8: 7 | B8: MOMIE Emilie
A9: 8 | B9: MONTE Valdese
A10: 9 | B10: NOUTSA Eugène
A11: 10 | B11: SONGOU Sainclaire
A12: 11 | B12: TAKOULEU Richardson
A13: 12 | B13: TCHIOFO Appolinie
A14: 13 | B14: TCHIOFO Fidélia | D14: 70000
A15: 14 | B15: TCHIOFO Paulin
A16: 15 | B16: TCHIOFO Rodine | F16: 30000
A17: 16 | B17: TCHIOFO Sorelle
A18: 17 | B18: TITNKHEU Moïse
A19: 18 | B19: WANGUN Parfait
A20: 19 | B20: YOUDOM Nadine
A21: 20 | B21: DAGOBERT | C21: 40000
A22: 21 | B22: DJEUNOU Donna | C22: 120000
A31: Total | C31: =SUM(C2:C30) -> 400000 | D31: =SUM(D2:D30) -> 256667 | E31: =SUM(E2:E30) -> 61667 | F31: =SUM(F2:F30) -> 90487 | G31: =SUM(G2:G30) -> 0 | H31: =SUM(H2:H30) -> 0 | I31: =SUM(I2:I30) -> 0 | J31: =SUM(J2:J30) -> 0 | ... X31: =SUM(X2:X30) -> 0
B33: Fonds transféré | C33: 850025 | E33: 200000 | F33: 134000 | G33: 50000
B34: Epargnes 2021 | F34: 350000
C35: =C31+C33 -> 1250025 | D35: =D31+D33 -> 256667 | E35: =E31+E33 -> 261667 | F35: =F31+F33+F34 -> 574487

Sheet apport_mensuel_calcul
A1: N° | B1: Nom épargnant | C1: Epargne Août. 2025 | D1: Interêt M | E1: Epargne Sept. 2025 | F1: AP. M+1 | G1: Intérêt M+1 | H1: Epargne Oct. 2025 | I1: AP. M+2 | J1: Intérêt M+2 | K1: Epargne Nov. 2025 | L1: AP. M+3 | M1: Intérêt M+3 | N1: Epargne Déc. 2025 | O1: AP. M+4 | P1: Intérêt M+4 | Q1: Epargne Janv. 2026 | R1: AP. M+5 | S1: Intérêt M+5 | T1: Epargne Fév. 2026 | U1: AP. M+6 | V1: Intérêt M+6 | W1: Epargne Mars. 2026 | X1: AP. M+7 | Y1: Intérêt M+7 | Z1: Epargne Avril. 2026 | AA1: AP. M+8 | AB1: Intérêt M+8 | AC1: Epargne Mai. 2026 | AD1: AP. M+9 | AE1: Intérêt M+9 | AF1: Epargne Juin. 2026 | AG1: AP. M+10 | AH1: Intérêt M+10 | AI1: Epargne Juil. 2026 | AJ1: AP. M+11 | AK1: Intérêt M+11 | AL1: Epargne Août. 2026 | AM1: AP. M+12 | AN1: Intérêt M+12 | AO1: Epargne Sept. 2026 | AP1: AP. M+13 | AQ1: Intérêt M+13 | AR1: Epargne Oct. 2026 | AS1: AP. M+14 | AT1: Intérêt M+14 | AU1: Epargne Nov. 2026 | AV1: AP. M+15 | AW1: Intérêt M+15 | AX1: Epargne Déc. 2026 | AY1: AP. M+16 | AZ1: Intérêt M+16 | BA1: Epargne Janv. 2027 | BB1: AP. M+17 | BC1: Intérêt M+17 | BD1: Epargne Fév. 2027 | BE1: AP. M+18 | BF1: Intérêt M+18 | BG1: Epargne Mars. 2027 | BH1: AP. M+19 | BI1: Intérêt M+19 | BJ1: Epargne Avril. 2027 | BK1: AP. M+20 | BL1: Intérêt M+20 | BM1: Epargne Mai. 2027 | BN1: AP. M+21 | BO1: Intérêt M+21 | BP1: Epargne Juin. 2027 | BQ1: AP. M+22 | BR1: Intérêt M+22 | BS1: Epargne Juil. 2027 | BT1: AP. M+23 | BU1: Intérêt M+23 | BV1: Total épargne | BW1: Total intérêt | BX1: Total théorique à percevoir | BY1: Bonus/Malus apuration anciennes dettes | BZ1: Total théorique +Bonus-Malus | CA1: Intérêt relatif | CB1: Part relative | CC1: Total net à percevoir
A2: =epargne_mensuelle!A2 -> 1 | B2: =epargne_mensuelle!B2 -> ACTIONNIRE1 | C2: =SUM(epargne_mensuelle!C2:E2) -> 956801.77 | D2: =(C2/C$48)*C$53 -> 120939.88 | E2: =epargne_mensuelle!F2 -> 0 | F2: =C2-(C2/C$48)*C$52+(C2/C$48)*C$53+E2+(C2/C$48)*C$54 -> 143244.18 | G2: =(F2/F$48)*E$53 -> 0 | H2: =epargne_mensuelle!G2 -> 0 | I2: =IF(F$48=0,F2+H2+((C2+E2)/(C$48+E$48))*E$54,F2-((F2/F$48)*E$52)+(F2/F$48)*E$53+H2+((C2+E2)/(C$48+E$48))*E$54) -> 163202.95 | J2: =(I2/I$48)*H$53 -> 15506.393 | K2: =epargne_mensuelle!H2 -> 0 | L2: =IF(I$48=0,I2+K2+((C2+E2+H2)/(C$48+E$48+H$48))*H$54,I2-((I2/I$48)*H$52)+(I2/I$48)*H$53+K2+((C2+E2+H2)/(C$48+E$48+H$48))*H$54) -> 138884.97 | M2: =(L2/L$48)*K$53 -> 5374.4158 | N2: =epargne_mensuelle!I2 -> 0 | O2: =IF(L$48=0,L2+N2+((C2+E2+H2+K2)/(C$48+E$48+H$48+K$48))*K$54,L2-((L2/L$48)*K$52)+(L2/L$48)*K$53+N2+((C2+E2+H2+K2)/(C$48+E$48+H$48+K$48))*K$54) -> 121697.98 | P2: =(O2/O$48)*N$53 -> 1924.1387 | Q2: =epargne_mensuelle!J2 -> 25000 | R2: =IF(O$48=0,O2+Q2+((C2+E2+H2+K2+N2)/(C$48+E$48+H$48+K$48+N$48))*N$54,O2-((O2/O$48)*N$52)+(O2/O$48)*N$53+Q2+((C2+E2+H2+K2+N2)/(C$48+E$48+H$48+K$48+N$48))*N$54) -> 213351.82 | S2: =(R2/R$48)*Q$53 -> 17729.448 | T2: =epargne_mensuelle!K2 -> 0 | U2: =IF(R$48=0,R2+T2+((C2+E2+H2+K2+N2+Q2)/(C$48+E$48+H$48+K$48+N$48+Q$48))*Q$54,R2-((R2/R$48)*Q$52)+(R2/R$48)*Q$53+T2+((C2+E2+H2+K2+N2+Q2)/(C$48+E$48+H$48+K$48+N$48+Q$48))*Q$54) -> 265756.74 | V2: =(U2/U$48)*T$53 -> 0 | W2: =epargne_mensuelle!L2 -> 0 | X2: =IF(U$48=0,U2+W2+((C2+E2+H2+K2+N2+Q2+T2)/(C$48+E$48+H$48+K$48+N$48+Q$48+T$48))*T$54,U2-((U2/U$48)*T$52)+(U2/U$48)*T$53+W2+((C2+E2+H2+K2+N2+Q2+T2)/(C$48+E$48+H$48+K$48+N$48+Q$48+T$48))*T$54) -> 265756.74 | Y2: =(X2/X$48)*W$53 -> 0 | Z2: =epargne_mensuelle!M2 -> 0 | AA2: =IF(X$48=0,X2+Z2+((C2+E2+H2+K2+N2+Q2+T2+W2)/(C$48+E$48+H$48+K$48+N$48+Q$48+T$48+W$48))*W$54,X2-((X2/X$48)*W$52)+(X2/X$48)*W$53+Z2+((C2+E2+H2+K2+N2+Q2+T2+W2)/(C$48+E$48+H$48+K$48+N$48+Q$48+T$48+W$48))*W$54) -> 265756.74 | AB2: =(AA2/AA$48)*Z$53 -> 0 | AC2: =epargne_mensuelle!N2 -> 0 | AD2: =IF(AA$48=0,AA2+AC2+((C2+E2+H2+K2+N2+Q2+T2+W2+Z2)/(C$48+E$48+H$48+K$48+N$48+Q$48+T$48+W$48+Z$48))*Z$54,AA2-((AA2/AA$48)*Z$52)+(AA2/AA$48)*Z$53+AC2+((C2+E2+H2+K2+N2+Q2+T2+W2+Z2)/(C$48+E$48+H$48+K$48+N$48+Q$48+T$48+W$48+Z$48))*Z$54) -> 265756.74 | AE2: =(AD2/AD$48)*AC$53 -> 0 | AF2: =epargne_mensuelle!O2 -> 0 | AG2: =IF(AD$48=0,AD2+AF2+((C2+E2+H2+K2+N2+Q2+T2+W2+Z2+AC2)/(C$48+E$48+H$48+K$48+N$48+Q$48+T$48+W$48+Z$48+AC$48))*AC$54,AD2-((AD2/AD$48)*AC$52)+(AD2/AD$48)*AC$53+AF2+((C2+E2+H2+K2+N2+Q2+T2+W2+Z2+AC2)/(C$48+E$48+H$48+K$48+N$48+Q$48+T$48+W$48+Z$48+AC$48))*AC$54) -> 265756.74 | AH2: =(AG2/AG$48)*AF$53 -> 0 | AI2: =epargne_mensuelle!P2 -> 0 | AJ2: =IF(AG$48=0,AG2+AI2+((C2+E2+H2+K2+N2+Q2+T2+W2+Z2+AC2+AF2)/(C$48+E$48+H$48+K$48+N$48+Q$48+T$48+W$48+Z$48+AC$48+AF$48))*AF$54,AG2-((AG2/AG$48)*AF$52)+(AG2/AG$48)*AF$53+AI2+((C2+E2+H2+K2+N2+Q2+T2+W2+Z2+AC2+AF2)/(C$48+E$48+H$48+K$48+N$48+Q$48+T$48+W$48+Z$48+AC$48+AF$48))*AF$54) -> 265756.74 | AK2: =(AJ2/AJ$48)*AI$53 -> 0 | AL2: =epargne_mensuelle!Q2 -> 0 | AM2: =IF(AJ$48=0,AJ2+AL2+((C2+E2+H2+K2+N2+Q2+T2+W2+Z2+AC2+AF2+AI2)/(C$48+E$48+H$48+K$48+N$48+Q$48+T$48+W$48+Z$48+AC$48+AF$48+AI$48))*AI$54,AJ2-((AJ2/AJ$48)*AI$52)+(AJ2/AJ$48)*AI$53+AL2+((C2+E2+H2+K2+N2+Q2+T2+W2+Z2+AC2+AF2+AI2)/(C$48+E$48+H$48+K$48+N$48+Q$48+T$48+W$48+Z$48+AC$48+AF$48+AI$48))*AI$54) -> 265756.74 | AN2: =(AM2/AM$48)*AL$53 -> 0 | AO2: =epargne_mensuelle!R2 -> 0 | AP2: =IF(AM$48=0,AM2+AO2+((C2+E2+H2+K2+N2+Q2+T2+W2+Z2+AC2+AF2+AI2+AL2)/(C$48+E$48+H$48+K$48+N$48+Q$48+T$48+W$48+Z$48+AC$48+AF$48+AI$48+AL$48))*AL$54,AM2-((AM2/AM$48)*AL$52)+(AM2/AM$48)*AL$53+AO2+((C2+E2+H2+K2+N2+Q2+T2+W2+Z2+AC2+AF2+AI2+AL2)/(C$48+E$48+H$48+K$48+N$48+Q$48+T$48+W$48+Z$48+AC$48+AF$48+AI$48+AL$48))*AL$54) -> 265756.74 | AQ2: =(AP2/AP$48)*AO$53 -> 0 | AR2: =epargne_mensuelle!S2 -> 0 | AS2: =IF(AP$48=0,AP2+AR2+((C2+E2+H2+K2+N2+Q2+T2+W2+Z2+AC2+AF2+AI2+AL2+AO2)/(C$48+E$48+H$48+K$48+N$48+Q$48+T$48+W$48+Z$48+AC$48+AF$48+AI$48+AL$48+AO$48))*AO$54,AP2-((AP2/AP$48)*AO$52)+(AP2/AP$48)*AO$53+AR2+((C2+E2+H2+K2+N2+Q2+T2+W2+Z2+AC2+AF2+AI2+AL2+AO2)/(C$48+E$48+H$48+K$48+N$48+Q$48+T$48+W$48+Z$48+AC$48+AF$48+AI$48+AL$48+AO$48))*AO$54) -> 265756.74 | AT2: =(AS2/AS$48)*AR$53 -> 0 | AU2: =epargne_mensuelle!T2 -> 0 | AV2: =IF(AS$48=0,AS2+AU2+((C2+E2+H2+K2+N2+Q2+T2+W2+Z2+AC2+AF2+AI2+AL2+AO2+AR2)/(C$48+E$48+H$48+K$48+N$48+Q$48+T$48+W$48+Z$48+AC$48+AF$48+AI$48+AL$48+AO$48+AR$48))*AR$54,AS2-((AS2/AS$48)*AR$52)+(AS2/AS$48)*AR$53+AU2+((C2+E2+H2+K2+N2+Q2+T2+W2+Z2+AC2+AF2+AI2+AL2+AO2+AR2)/(C$48+E$48+H$48+K$48+N$48+Q$48+T$48+W$48+Z$48+AC$48+AF$48+AI$48+AL$48+AO$48+AR$48))*AR$54) -> 265756.74 | AW2: =(AV2/AV$48)*AU$53 -> 0 | AX2: =epargne_mensuelle!U2 -> 0 | AY2: =IF(AV$48=0,AV2+AX2+((C2+E2+H2+K2+N2+Q2+T2+W2+Z2+AC2+AF2+AI2+AL2+AO2+AR2+AU2)/(C$48+E$48+H$48+K$48+N$48+Q$48+T$48+W$48+Z$48+AC$48+AF$48+AI$48+AL$48+AO$48+AR$48+AU$48))*AU$54,AV2-((AV2/AV$48)*AU$52)+(AV2/AV$48)*AU$53+AX2+((C2+E2+H2+K2+N2+Q2+T2+W2+Z2+AC2+AF2+AI2+AL2+AO2+AR2+AU2)/(C$48+E$48+H$48+K$48+N$48+Q$48+T$48+W$48+Z$48+AC$48+AF$48+AI$48+AL$48+AO$48+AR$48+AU$48))*AU$54) -> 265756.74 | AZ2: =(AY2/AY$48)*AX$53 -> 0 | BA2: =epargne_mensuelle!V2 -> 0 | BB2: =IF(AY$48=0,AY2+BA2+((C2+E2+H2+K2+N2+Q2+T2+W2+Z2+AC2+AF2+AI2+AL2+AO2+AR2+AU2+AX2)/(C$48+E$48+H$48+K$48+N$48+Q$48+T$48+W$48+Z$48+AC$48+AF$48+AI$48+AL$48+AO$48+AR$48+AU$48+AX$48))*AX$54,AY2-((AY2/AY$48)*AX$52)+(AY2/AY$48)*AX$53+BA2+((C2+E2+H2+K2+N2+Q2+T2+W2+Z2+AC2+AF2+AI2+AL2+AO2+AR2+AU2+AX2)/(C$48+E$48+H$48+K$48+N$48+Q$48+T$48+W$48+Z$48+AC$48+AF$48+AI$48+AL$48+AO$48+AR$48+AU$48+AX$48))*AX$54) -> 265756.74 | BC2: =(BB2/BB$48)*BA$53 -> 0 | BD2: =epargne_mensuelle!W2 -> 0 | BE2: =IF(BB$48=0,BB2+BD2+((C2+E2+H2+K2+N2+Q2+T2+W2+Z2+AC2+AF2+AI2+AL2+AO2+AR2+AU2+AX2+BA2)/(C$48+E$48+H$48+K$48+N$48+Q$48+T$48+W$48+Z$48+AC$48+AF$48+AI$48+AL$48+AO$48+AR$48+AU$48+AX$48+BA$48))*BA$54,BB2-((BB2/BB$48)*BA$52)+(BB2/BB$48)*BA$53+BD2+((C2+E2+H2+K2+N2+Q2+T2+W2+Z2+AC2+AF2+AI2+AL2+AO2+AR2+AU2+AX2+BA2)/(C$48+E$48+H$48+K$48+N$48+Q$48+T$48+W$48+Z$48+AC$48+AF$48+AI$48+AL$48+AO$48+AR$48+AU$48+AX$48+BA$48))*BA$54) -> 265756.74 | BF2: =(BE2/BE$48)*BD$53 -> 0 | BG2: =epargne_mensuelle!X2 -> 0 | BH2: =IF(BE$48=0,BE2+BG2+((C2+E2+H2+K2+N2+Q2+T2+W2+Z2+AC2+AF2+AI2+AL2+AO2+AR2+AU2+AX2+BA2+BD2)/(C$48+E$48+H$48+K$48+N$48+Q$48+T$48+W$48+Z$48+AC$48+AF$48+AI$48+AL$48+AO$48+AR$48+AU$48+AX$48+BA$48+BD$48))*BD$54,BE2-((BE2/BE$48)*BD$52)+(BE2/BE$48)*BD$53+BG2+((C2+E2+H2+K2+N2+Q2+T2+W2+Z2+AC2+AF2+AI2+AL2+AO2+AR2+AU2+AX2+BA2+BD2)/(C$48+E$48+H$48+K$48+N$48+Q$48+T$48+W$48+Z$48+AC$48+AF$48+AI$48+AL$48+AO$48+AR$48+AU$48+AX$48+BA$48+BD$48))*BD$54) -> 265756.74 | BI2: =(BH2/BH$48)*BG$53 -> 0 | BJ2: =epargne_mensuelle!Y2 -> 0 | BK2: =IF(BH$48=0,BH2+BJ2+((C2+E2+H2+K2+N2+Q2+T2+W2+Z2+AC2+AF2+AI2+AL2+AO2+AR2+AU2+AX2+BA2+BD2+BG2)/(C$48+E$48+H$48+K$48+N$48+Q$48+T$48+W$48+Z$48+AC$48+AF$48+AI$48+AL$48+AO$48+AR$48+AU$48+AX$48+BA$48+BD$48+BG$48))*BG$54,BH2-((BH2/BH$48)*BG$52)+(BH2/BH$48)*BG$53+BJ2+((C2+E2+H2+K2+N2+Q2+T2+W2+Z2+AC2+AF2+AI2+AL2+AO2+AR2+AU2+AX2+BA2+BD2+BG2)/(C$48+E$48+H$48+K$48+N$48+Q$48+T$48+W$48+Z$48+AC$48+AF$48+AI$48+AL$48+AO$48+AR$48+AU$48+AX$48+BA$48+BD$48+BG$48))*BG$54) -> 265756.74 | BL2: =(BK2/BK$48)*BJ$53 -> 0 | BM2: =epargne_mensuelle!Z2 -> 0 | BN2: =IF(BK$48=0,BK2+BM2+((C2+E2+H2+K2+N2+Q2+T2+W2+Z2+AC2+AF2+AI2+AL2+AO2+AR2+AU2+AX2+BA2+BD2+BG2+BJ2)/(C$48+E$48+H$48+K$48+N$48+Q$48+T$48+W$48+Z$48+AC$48+AF$48+AI$48+AL$48+AO$48+AR$48+AU$48+AX$48+BA$48+BD$48+BG$48+BJ$48))*BJ$54,BK2-((BK2/BK$48)*BJ$52)+(BK2/BK$48)*BJ$53+BM2+((C2+E2+H2+K2+N2+Q2+T2+W2+Z2+AC2+AF2+AI2+AL2+AO2+AR2+AU2+AX2+BA2+BD2+BG2+BJ2)/(C$48+E$48+H$48+K$48+N$48+Q$48+T$48+W$48+Z$48+AC$48+AF$48+AI$48+AL$48+AO$48+AR$48+AU$48+AX$48+BA$48+BD$48+BG$48+BJ$48))*BJ$54) -> 265756.74 | BO2: =(BN2/BN$48)*BM$53 -> 0 | BP2: =epargne_mensuelle!AA2 -> 0 | BQ2: =IF(BN$48=0,BN2+BP2+((F2+H2+K2+N2+Q2+T2+W2+Z2+AC2+AF2+AI2+AL2+AO2+AR2+AU2+AX2+BA2+BD2+BG2+BJ2+BM2)/(F$48+H$48+K$48+N$48+Q$48+T$48+W$48+Z$48+AC$48+AF$48+AI$48+AL$48+AO$48+AR$48+AU$48+AX$48+BA$48+BD$48+BG$48+BJ$48+BM$48))*BM$54,BN2-((BN2/BN$48)*BM$52)+(BN2/BN$48)*BM$53+BP2+((F2+H2+K2+N2+Q2+T2+W2+Z2+AC2+AF2+AI2+AL2+AO2+AR2+AU2+AX2+BA2+BD2+BG2+BJ2+BM2)/(F$48+H$48+K$48+N$48+Q$48+T$48+W$48+Z$48+AC$48+AF$48+AI$48+AL$48+AO$48+AR$48+AU$48+AX$48+BA$48+BD$48+BG$48+BJ$48+BM$48))*BM$54) -> 265756.74 | BR2: =(BQ2/BQ$48)*BP$53 -> 0 | BS2: =epargne_mensuelle!AB2 -> 0 | BT2: =IF(BQ$48=0,BQ2+BS2+((I2+K2+N2+Q2+T2+W2+Z2+AC2+AF2+AI2+AL2+AO2+AR2+AU2+AX2+BA2+BD2+BG2+BJ2+BM2+BP2)/(I$48+K$48+N$48+Q$48+T$48+W$48+Z$48+AC$48+AF$48+AI$48+AL$48+AO$48+AR$48+AU$48+AX$48+BA$48+BD$48+BG$48+BJ$48+BM$48+BP$48))*BP$54,BQ2-((BQ2/BQ$48)*BP$52)+(BQ2/BQ$48)*BP$53+BS2+((I2+K2+N2+Q2+T2+W2+Z2+AC2+AF2+AI2+AL2+AO2+AR2+AU2+AX2+BA2+BD2+BG2+BJ2+BM2+BP2)/(I$48+K$48+N$48+Q$48+T$48+W$48+Z$48+AC$48+AF$48+AI$48+AL$48+AO$48+AR$48+AU$48+AX$48+BA$48+BD$48+BG$48+BJ$48+BM$48+BP$48))*BP$54) -> 265756.74 | BU2: =(BT2/BT$48)*BS$53 -> 0 | BV2: =cumul_epargne!C2 -> 981801.77 | BW2: =D2+G2+J2+M2+P2+S2+V2+Y2+AB2+AE2+AH2+AK2+AN2+AQ2+AT2+AW2+AZ2+BC2+BF2+BI2+BL2+BO2+BR2+BU2 -> 161474.28 | BX2: =IF(BV2="",BW2,BV2+BW2) -> 1143276.1 | BZ2: =BX2+BY2 -> 1143276.1 | CA2: =IF(BV2="","",BW2/BV2) -> 0.16446729 | CB2: =BZ2/BZ$48 -> 0.025200719 | CC2: =CB2*(C$50-BW$58-BW$57) -> 109088.95 | CD2: =B2 -> ACTIONNIRE1
A3: =epargne_mensuelle!A3 -> 2 | B3: =epargne_mensuelle!B3 -> ACTIONNIRE2 | C3: =SUM(epargne_mensuelle!C3:E3) -> 270897.47 | D3: =(C3/C$48)*C$53 -> 34241.48 | E3: =epargne_mensuelle!F3 -> 0 | F3: =C3-(C3/C$48)*C$52+(C3/C$48)*C$53+E3+(C3/C$48)*C$54 -> 40556.453 | G3: =(F3/F$48)*E$53 -> 0 | H3: =epargne_mensuelle!G3 -> 300000 | I3: =IF(F$48=0,F3+H3+((C3+E3)/(C$48+E$48))*E$54,F3-((F3/F$48)*E$52)+(F3/F$48)*E$53+H3+((C3+E3)/(C$48+E$48))*E$54) -> 346207.34 | J3: =(I3/I$48)*H$53 -> 32894.179 | K3: =epargne_mensuelle!H3 -> 0 | L3: =IF(I$48=0,I3+K3+((C3+E3+H3)/(C$48+E$48+H$48))*H$54,I3-((I3/I$48)*H$52)+(I3/I$48)*H$53+K3+((C3+E3+H3)/(C$48+E$48+H$48))*H$54) -> 167933.8 | M3: =(L3/L$48)*K$53 -> 6498.515 | N3: =epargne_mensuelle!I3 -> 0 | O3: =IF(L$48=0,L3+N3+((C3+E3+H3+K3)/(C$48+E$48+H$48+K$48))*K$54,L3-((L3/L$48)*K$52)+(L3/L$48)*K$53+N3+((C3+E3+H3+K3)/(C$48+E$48+H$48+K$48))*K$54) -> 107160.87 | P3: =(O3/O$48)*N$53 -> 1694.2958 | Q3: =epargne_mensuelle!J3 -> 0 | R3: =IF(O$48=0,O3+Q3+((C3+E3+H3+K3+N3)/(C$48+E$48+H$48+K$48+N$48))*N$54,O3-((O3/O$48)*N$52)+(O3/O$48)*N$53+Q3+((C3+E3+H3+K3+N3)/(C$48+E$48+H$48+K$48+N$48))*N$54) -> 133822.24 | S3: =(R3/R$48)*Q$53 -> 11120.573 | T3: =epargne_mensuelle!K3 -> 0 | U3: =IF(R$48=0,R3+T3+((C3+E3+H3+K3+N3+Q3)/(C$48+E$48+H$48+K$48+N$48+Q$48))*Q$54,R3-((R3/R$48)*Q$52)+(R3/R$48)*Q$53+T3+((C3+E3+H3+K3+N3+Q3)/(C$48+E$48+H$48+K$48+N$48+Q$48))*Q$54) -> 161725.61 | V3: =(U3/U$48)*T$53 -> 0 | W3: =epargne_mensuelle!L3 -> 0 | X3: =IF(U$48=0,U3+W3+((C3+E3+H3+K3+N3+Q3+T3)/(C$48+E$48+H$48+K$48+N$48+Q$48+T$48))*T$54,U3-((U3/U$48)*T$52)+(U3/U$48)*T$53+W3+((C3+E3+H3+K3+N3+Q3+T3)/(C$48+E$48+H$48+K$48+N$48+Q$48+T$48))*T$54) -> 161725.61 | Y3: =(X3/X$48)*W$53 -> 0 | Z3: =epargne_mensuelle!M3 -> 0 | AA3: =IF(X$48=0,X3+Z3+((C3+E3+H3+K3+N3+Q3+T3+W3)/(C$48+E$48+H$48+K$48+N$48+Q$48+T$48+W$48))*W$54,X3-((X3/X$48)*W$52)+(X3/X$48)*W$53+Z3+((C3+E3+H3+K3+N3+Q3+T3+W3)/(C$48+E$48+H$48+K$48+N$48+Q$48+T$48+W$48))*W$54) -> 161725.61 | AB3: =(AA3/AA$48)*Z$53 -> 0 | AC3: =epargne_mensuelle!N3 -> 0 | AD3: =IF(AA$48=0,AA3+AC3+((C3+E3+H3+K3+N3+Q3+T3+W3+Z3)/(C$48+E$48+H$48+K$48+N$48+Q$48+T$48+W$48+Z$48))*Z$54,AA3-((AA3/AA$48)*Z$52)+(AA3/AA$48)*Z$53+AC3+((C3+E3+H3+K3+N3+Q3+T3+W3+Z3)/(C$48+E$48+H$48+K$48+N$48+Q$48+T$48+W$48+Z$48))*Z$54) -> 161725.61 | AE3: =(AD3/AD$48)*AC$53 -> 0 | AF3: =epargne_mensuelle!O3 -> 0 | AG3: =IF(AD$48=0,AD3+AF3+((C3+E3+H3+K3+N3+Q3+T3+W3+Z3+AC3)/(C$48+E$48+H$48+K$48+N$48+Q$48+T$48+W$48+Z$48+AC$48))*AC$54,AD3-((AD3/AD$48)*AC$52)+(AD3/AD$48)*AC$53+AF3+((C3+E3+H3+K3+N3+Q3+T3+W3+Z3+AC3)/(C$48+E$48+H$48+K$48+N$48+Q$48+T$48+W$48+Z$48+AC$48))*AC$54) -> 161725.61 | AH3: =(AG3/AG$48)*AF$53 -> 0 | AI3: =epargne_mensuelle!P3 -> 0 | AJ3: =IF(AG$48=0,AG3+AI3+((C3+E3+H3+K3+N3+Q3+T3+W3+Z3+AC3+AF3)/(C$48+E$48+H$48+K$48+N$48+Q$48+T$48+W$48+Z$48+AC$48+AF$48))*AF$54,AG3-((AG3/AG$48)*AF$52)+(AG3/AG$48)*AF$53+AI3+((C3+E3+H3+K3+N3+Q3+T3+W3+Z3+AC3+AF3)/(C$48+E$48+H$48+K$48+N$48+Q$48+T$48+W$48+Z$48+AC$48+AF$48))*AF$54) -> 161725.61 | AK3: =(AJ3/AJ$48)*AI$53 -> 0 | AL3: =epargne_mensuelle!Q3 -> 0 | AM3: =IF(AJ$48=0,AJ3+AL3+((C3+E3+H3+K3+N3+Q3+T3+W3+Z3+AC3+AF3+AI3)/(C$48+E$48+H$48+K$48+N$48+Q$48+T$48+W$48+Z$48+AC$48+AF$48+AI$48))*AI$54,AJ3-((AJ3/AJ$48)*AI$52)+(AJ3/AJ$48)*AI$53+AL3+((C3+E3+H3+K3+N3+Q3+T3+W3+Z3+AC3+AF3+AI3)/(C$48+E$48+H$48+K$48+N$48+Q$48+T$48+W$48+Z$48+AC$48+AF$48+AI$48))*AI$54) -> 161725.61 | AN3: =(AM3/AM$48)*AL$53 -> 0 | AO3: =epargne_mensuelle!R3 -> 0 | AP3: =IF(AM$48=0,AM3+AO3+((C3+E3+H3+K3+N3+Q3+T3+W3+Z3+AC3+AF3+AI3+AL3)/(C$48+E$48+H$48+K$48+N$48+Q$48+T$48+W$48+Z$48+AC$48+AF$48+AI$48+AL$48))*AL$54,AM3-((AM3/AM$48)*AL$52)+(AM3/AM$48)*AL$53+AO3+((C3+E3+H3+K3+N3+Q3+T3+W3+Z3+AC3+AF3+AI3+AL3)/(C$48+E$48+H$48+K$48+N$48+Q$48+T$48+W$48+Z$48+AC$48+AF$48+AI$48+AL$48))*AL$54) -> 161725.61 | AQ3: =(AP3/AP$48)*AO$53 -> 0 | AR3: =epargne_mensuelle!S3 -> 0 | AS3: =IF(AP$48=0,AP3+AR3+((C3+E3+H3+K3+N3+Q3+T3+W3+Z3+AC3+AF3+AI3+AL3+AO3)/(C$48+E$48+H$48+K$48+N$48+Q$48+T$48+W$48+Z$48+AC$48+AF$48+AI$48+AL$48+AO$48))*AO$54,AP3-((AP3/AP$48)*AO$52)+(AP3/AP$48)*AO$53+AR3+((C3+E3+H3+K3+N3+Q3+T3+W3+Z3+AC3+AF3+AI3+AL3+AO3)/(C$48+E$48+H$48+K$48+N$48+Q$48+T$48+W$48+Z$48+AC$48+AF$48+AI$48+AL$48+AO$48))*AO$54) -> 161725.61 | AT3: =(AS3/AS$48)*AR$53 -> 0 | AU3: =epargne_mensuelle!T3 -> 0 | AV3: =IF(AS$48=0,AS3+AU3+((C3+E3+H3+K3+N3+Q3+T3+W3+Z3+AC3+AF3+AI3+AL3+AO3+AR3)/(C$48+E$48+H$48+K$48+N$48+Q$48+T$48+W$48+Z$48+AC$48+AF$48+AI$48+AL$48+AO$48+AR$48))*AR$54,AS3-((AS3/AS$48)*AR$52)+(AS3/AS$48)*AR$53+AU3+((C3+E3+H3+K3+N3+Q3+T3+W3+Z3+AC3+AF3+AI3+AL3+AO3+AR3)/(C$48+E$48+H$48+K$48+N$48+Q$48+T$48+W$48+Z$48+AC$48+AF$48+AI$48+AL$48+AO$48+AR$48))*AR$54) -> 161725.61 | AW3: =(AV3/AV$48)*AU$53 -> 0 | AX3: =epargne_mensuelle!U3 -> 0 | AY3: =IF(AV$48=0,AV3+AX3+((C3+E3+H3+K3+N3+Q3+T3+W3+Z3+AC3+AF3+AI3+AL3+AO3+AR3+AU3)/(C$48+E$48+H$48+K$48+N$48+Q$48+T$48+W$48+Z$48+AC$48+AF$48+AI$48+AL$48+AO$48+AR$48+AU$48))*AU$54,AV3-((AV3/AV$48)*AU$52)+(AV3/AV$48)*AU$53+AX3+((C3+E3+H3+K3+N3+Q3+T3+W3+Z3+AC3+AF3+AI3+AL3+AO3+AR3+AU3)/(C$48+E$48+H$48+K$48+N$48+Q$48+T$48+W$48+Z$48+AC$48+AF$48+AI$48+AL$48+AO$48+AR$48+AU$48))*AU$54) -> 161725.61 | AZ3: =(AY3/AY$48)*AX$53 -> 0 | BA3: =epargne_mensuelle!V3 -> 0 | BB3: =IF(AY$48=0,AY3+BA3+((C3+E3+H3+K3+N3+Q3+T3+W3+Z3+AC3+AF3+AI3+AL3+AO3+AR3+AU3+AX3)/(C$48+E$48+H$48+K$48+N$48+Q$48+T$48+W$48+Z$48+AC$48+AF$48+AI$48+AL$48+AO$48+AR$48+AU$48+AX$48))*AX$54,AY3-((AY3/AY$48)*AX$52)+(AY3/AY$48)*AX$53+BA3+((C3+E3+H3+K3+N3+Q3+T3+W3+Z3+AC3+AF3+AI3+AL3+AO3+AR3+AU3+AX3)/(C$48+E$48+H$48+K$48+N$48+Q$48+T$48+W$48+Z$48+AC$48+AF$48+AI$48+AL$48+AO$48+AR$48+AU$48+AX$48))*AX$54) -> 161725.61 | BC3: =(BB3/BB$48)*BA$53 -> 0 | BD3: =epargne_mensuelle!W3 -> 0 | BE3: =IF(BB$48=0,BB3+BD3+((C3+E3+H3+K3+N3+Q3+T3+W3+Z3+AC3+AF3+AI3+AL3+AO3+AR3+AU3+AX3+BA3)/(C$48+E$48+H$48+K$48+N$48+Q$48+T$48+W$48+Z$48+AC$48+AF$48+AI$48+AL$48+AO$48+AR$48+AU$48+AX$48+BA$48))*BA$54,BB3-((BB3/BB$48)*BA$52)+(BB3/BB$48)*BA$53+BD3+((C3+E3+H3+K3+N3+Q3+T3+W3+Z3+AC3+AF3+AI3+AL3+AO3+AR3+AU3+AX3+BA3)/(C$48+E$48+H$48+K$48+N$48+Q$48+T$48+W$48+Z$48+AC$48+AF$48+AI$48+AL$48+AO$48+AR$48+AU$48+AX$48+BA$48))*BA$54) -> 161725.61 | BF3: =(BE3/BE$48)*BD$53 -> 0 | BG3: =epargne_mensuelle!X3 -> 0 | BH3: =IF(BE$48=0,BE3+BG3+((C3+E3+H3+K3+N3+Q3+T3+W3+Z3+AC3+AF3+AI3+AL3+AO3+AR3+AU3+AX3+BA3+BD3)/(C$48+E$48+H$48+K$48+N$48+Q$48+T$48+W$48+Z$48+AC$48+AF$48+AI$48+AL$48+AO$48+AR$48+AU$48+AX$48+BA$48+BD$48))*BD$54,BE3-((BE3/BE$48)*BD$52)+(BE3/BE$48)*BD$53+BG3+((C3+E3+H3+K3+N3+Q3+T3+W3+Z3+AC3+AF3+AI3+AL3+AO3+AR3+AU3+AX3+BA3+BD3)/(C$48+E$48+H$48+K$48+N$48+Q$48+T$48+W$48+Z$48+AC$48+AF$48+AI$48+AL$48+AO$48+AR$48+AU$48+AX$48+BA$48+BD$48))*BD$54) -> 161725.61 | BI3: =(BH3/BH$48)*BG$53 -> 0 | BJ3: =epargne_mensuelle!Y3 -> 0 | BK3: =IF(BH$48=0,BH3+BJ3+((C3+E3+H3+K3+N3+Q3+T3+W3+Z3+AC3+AF3+AI3+AL3+AO3+AR3+AU3+AX3+BA3+BD3+BG3)/(C$48+E$48+H$48+K$48+N$48+Q$48+T$48+W$48+Z$48+AC$48+AF$48+AI$48+AL$48+AO$48+AR$48+AU$48+AX$48+BA$48+BD$48+BG$48))*BG$54,BH3-((BH3/BH$48)*BG$52)+(BH3/BH$48)*BG$53+BJ3+((C3+E3+H3+K3+N3+Q3+T3+W3+Z3+AC3+AF3+AI3+AL3+AO3+AR3+AU3+AX3+BA3+BD3+BG3)/(C$48+E$48+H$48+K$48+N$48+Q$48+T$48+W$48+Z$48+AC$48+AF$48+AI$48+AL$48+AO$48+AR$48+AU$48+AX$48+BA$48+BD$48+BG$48))*BG$54) -> 161725.61 | BL3: =(BK3/BK$48)*BJ$53 -> 0 | BM3: =epargne_mensuelle!Z3 -> 0 | BN3: =IF(BK$48=0,BK3+BM3+((C3+E3+H3+K3+N3+Q3+T3+W3+Z3+AC3+AF3+AI3+AL3+AO3+AR3+AU3+AX3+BA3+BD3+BG3+BJ3)/(C$48+E$48+H$48+K$48+N$48+Q$48+T$48+W$48+Z$48+AC$48+AF$48+AI$48+AL$48+AO$48+AR$48+AU$48+AX$48+BA$48+BD$48+BG$48+BJ$48))*BJ$54,BK3-((BK3/BK$48)*BJ$52)+(BK3/BK$48)*BJ$53+BM3+((C3+E3+H3+K3+N3+Q3+T3+W3+Z3+AC3+AF3+AI3+AL3+AO3+AR3+AU3+AX3+BA3+BD3+BG3+BJ3)/(C$48+E$48+H$48+K$48+N$48+Q$48+T$48+W$48+Z$48+AC$48+AF$48+AI$48+AL$48+AO$48+AR$48+AU$48+AX$48+BA$48+BD$48+BG$48+BJ$48))*BJ$54) -> 161725.61 | BO3: =(BN3/BN$48)*BM$53 -> 0 | BP3: =epargne_mensuelle!AA3 -> 0 | BQ3: =IF(BN$48=0,BN3+BP3+((F3+H3+K3+N3+Q3+T3+W3+Z3+AC3+AF3+AI3+AL3+AO3+AR3+AU3+AX3+BA3+BD3+BG3+BJ3+BM3)/(F$48+H$48+K$48+N$48+Q$48+T$48+W$48+Z$48+AC$48+AF$48+AI$48+AL$48+AO$48+AR$48+AU$48+AX$48+BA$48+BD$48+BG$48+BJ$48+BM$48))*BM$54,BN3-((BN3/BN$48)*BM$52)+(BN3/BN$48)*BM$53+BP3+((F3+H3+K3+N3+Q3+T3+W3+Z3+AC3+AF3+AI3+AL3+AO3+AR3+AU3+AX3+BA3+BD3+BG3+BJ3+BM3)/(F$48+H$48+K$48+N$48+Q$48+T$48+W$48+Z$48+AC$48+AF$48+AI$48+AL$48+AO$48+AR$48+AU$48+AX$48+BA$48+BD$48+BG$48+BJ$48+BM$48))*BM$54) -> 161725.61 | BR3: =(BQ3/BQ$48)*BP$53 -> 0 | BS3: =epargne_mensuelle!AB3 -> 0 | BT3: =IF(BQ$48=0,BQ3+BS3+((I3+K3+N3+Q3+T3+W3+Z3+AC3+AF3+AI3+AL3+AO3+AR3+AU3+AX3+BA3+BD3+BG3+BJ3+BM3+BP3)/(I$48+K$48+N$48+Q$48+T$48+W$48+Z$48+AC$48+AF$48+AI$48+AL$48+AO$48+AR$48+AU$48+AX$48+BA$48+BD$48+BG$48+BJ$48+BM$48+BP$48))*BP$54,BQ3-((BQ3/BQ$48)*BP$52)+(BQ3/BQ$48)*BP$53+BS3+((I3+K3+N3+Q3+T3+W3+Z3+AC3+AF3+AI3+AL3+AO3+AR3+AU3+AX3+BA3+BD3+BG3+BJ3+BM3+BP3)/(I$48+K$48+N$48+Q$48+T$48+W$48+Z$48+AC$48+AF$48+AI$48+AL$48+AO$48+AR$48+AU$48+AX$48+BA$48+BD$48+BG$48+BJ$48+BM$48+BP$48))*BP$54) -> 161725.61 | BU3: =(BT3/BT$48)*BS$53 -> 0 | BV3: =cumul_epargne!C3 -> 570897.47 | BW3: =D3+G3+J3+M3+P3+S3+V3+Y3+AB3+AE3+AH3+AK3+AN3+AQ3+AT3+AW3+AZ3+BC3+BF3+BI3+BL3+BO3+BR3+BU3 -> 86449.043 | BX3: =IF(BV3="",BW3,BV3+BW3) -> 657346.51 | BZ3: =BX3+BY3 -> 657346.51 | CA3: =IF(BV3="","",BW3/BV3) -> 0.15142657 | CB3: =BZ3/BZ$48 -> 0.014489593 | CC3: =CB3*(C$50-BW$58-BW$57) -> 62722.594 | CD3: =B3 -> ACTIONNIRE2
A4: =epargne_mensuelle!A4 -> 3 | B4: =epargne_mensuelle!B4 -> ACTIONNIRE3 | C4: =SUM(epargne_mensuelle!C4:E4) -> 4008079.8 | D4: =(C4/C$48)*C$53 -> 506621.87 | E4: =epargne_mensuelle!F4 -> 0 | F4: =C4-(C4/C$48)*C$52+(C4/C$48)*C$53+E4+(C4/C$48)*C$54 -> 600055.43 | G4: =(F4/F$48)*E$53 -> 0 | H4: =epargne_mensuelle!G4 -> 0 | I4: =IF(F$48=0,F4+H4+((C4+E4)/(C$48+E$48))*E$54,F4-((F4/F$48)*E$52)+(F4/F$48)*E$53+H4+((C4+E4)/(C$48+E$48))*E$54) -> 683663.51 | J4: =(I4/I$48)*H$53 -> 64956.883 | K4: =epargne_mensuelle!H4 -> 0 | L4: =IF(I$48=0,I4+K4+((C4+E4+H4)/(C$48+E$48+H$48))*H$54,I4-((I4/I$48)*H$52)+(I4/I$48)*H$53+K4+((C4+E4+H4)/(C$48+E$48+H$48))*H$54) -> 581794.52 | M4: =(L4/L$48)*K$53 -> 22513.636 | N4: =epargne_mensuelle!I4 -> 0 | O4: =IF(L$48=0,L4+N4+((C4+E4+H4+K4)/(C$48+E$48+H$48+K$48))*K$54,L4-((L4/L$48)*K$52)+(L4/L$48)*K$53+N4+((C4+E4+H4+K4)/(C$48+E$48+H$48+K$48))*K$54) -> 509797.57 | P4: =(O4/O$48)*N$53 -> 8060.2917 | Q4: =epargne_mensuelle!J4 -> 0 | R4: =IF(O$48=0,O4+Q4+((C4+E4+H4+K4+N4)/(C$48+E$48+H$48+K$48+N$48))*N$54,O4-((O4/O$48)*N$52)+(O4/O$48)*N$53+Q4+((C4+E4+H4+K4+N4)/(C$48+E$48+H$48+K$48+N$48))*N$54) -> 789013.09 | S4: =(R4/R$48)*Q$53 -> 65566.662 | T4: =epargne_mensuelle!K4 -> 0 | U4: =IF(R$48=0,R4+T4+((C4+E4+H4+K4+N4+Q4)/(C$48+E$48+H$48+K$48+N$48+Q$48))*Q$54,R4-((R4/R$48)*Q$52)+(R4/R$48)*Q$53+T4+((C4+E4+H4+K4+N4+Q4)/(C$48+E$48+H$48+K$48+N$48+Q$48))*Q$54) -> 1024519.3 | V4: =(U4/U$48)*T$53 -> 0 | W4: =epargne_mensuelle!L4 -> 0 | X4: =IF(U$48=0,U4+W4+((C4+E4+H4+K4+N4+Q4+T4)/(C$48+E$48+H$48+K$48+N$48+Q$48+T$48))*T$54,U4-((U4/U$48)*T$52)+(U4/U$48)*T$53+W4+((C4+E4+H4+K4+N4+Q4+T4)/(C$48+E$48+H$48+K$48+N$48+Q$48+T$48))*T$54) -> 1024519.3 | Y4: =(X4/X$48)*W$53 -> 0 | Z4: =epargne_mensuelle!M4 -> 0 | AA4: =IF(X$48=0,X4+Z4+((C4+E4+H4+K4+N4+Q4+T4+W4)/(C$48+E$48+H$48+K$48+N$48+Q$48+T$48+W$48))*W$54,X4-((X4/X$48)*W$52)+(X4/X$48)*W$53+Z4+((C4+E4+H4+K4+N4+Q4+T4+W4)/(C$48+E$48+H$48+K$48+N$48+Q$48+T$48+W$48))*W$54) -> 1024519.3 | AB4: =(AA4/AA$48)*Z$53 -> 0 | AC4: =epargne_mensuelle!N4 -> 0 | AD4: =IF(AA$48=0,AA4+AC4+((C4+E4+H4+K4+N4+Q4+T4+W4+Z4)/(C$48+E$48+H$48+K$48+N$48+Q$48+T$48+W$48+Z$48))*Z$54,AA4-((AA4/AA$48)*Z$52)+(AA4/AA$48)*Z$53+AC4+((C4+E4+H4+K4+N4+Q4+T4+W4+Z4)/(C$48+E$48+H$48+K$48+N$48+Q$48+T$48+W$48+Z$48))*Z$54) -> 1024519.3 | AE4: =(AD4/AD$48)*AC$53 -> 0 | AF4: =epargne_mensuelle!O4 -> 0 | AG4: =IF(AD$48=0,AD4+AF4+((C4+E4+H4+K4+N4+Q4+T4+W4+Z4+AC4)/(C$48+E$48+H$48+K$48+N$48+Q$48+T$48+W$48+Z$48+AC$48))*AC$54,AD4-((AD4/AD$48)*AC$52)+(AD4/AD$48)*AC$53+AF4+((C4+E4+H4+K4+N4+Q4+T4+W4+Z4+AC4)/(C$48+E$48+H$48+K$48+N$48+Q$48+T$48+W$48+Z$48+AC$48))*AC$54) -> 1024519.3 | AH4: =(AG4/AG$48)*AF$53 -> 0 | AI4: =epargne_mensuelle!P4 -> 0 | AJ4: =IF(AG$48=0,AG4+AI4+((C4+E4+H4+K4+N4+Q4+T4+W4+Z4+AC4+AF4)/(C$48+E$48+H$48+K$48+N$48+Q$48+T$48+W$48+Z$48+AC$48+AF$48))*AF$54,AG4-((AG4/AG$48)*AF$52)+(AG4/AG$48)*AF$53+AI4+((C4+E4+H4+K4+N4+Q4+T4+W4+Z4+AC4+AF4)/(C$48+E$48+H$48+K$48+N$48+Q$48+T$48+W$48+Z$48+AC$48+AF$48))*AF$54) -> 1024519.3 | AK4: =(AJ4/AJ$48)*AI$53 -> 0 | AL4: =epargne_mensuelle!Q4 -> 0 | AM4: =IF(AJ$48=0,AJ4+AL4+((C4+E4+H4+K4+N4+Q4+T4+W4+Z4+AC4+AF4+AI4)/(C$48+E$48+H$48+K$48+N$48+Q$48+T$48+W$48+Z$48+AC$48+AF$48+AI$48))*AI$54,AJ4-((AJ4/AJ$48)*AI$52)+(AJ4/AJ$48)*AI$53+AL4+((C4+E4+H4+K4+N4+Q4+T4+W4+Z4+AC4+AF4+AI4)/(C$48+E$48+H$48+K$48+N$48+Q$48+T$48+W$48+Z$48+AC$48+AF$48+AI$48))*AI$54) -> 1024519.3 | AN4: =(AM4/AM$48)*AL$53 -> 0 | AO4: =epargne_mensuelle!R4 -> 0 | AP4: =IF(AM$48=0,AM4+AO4+((C4+E4+H4+K4+N4+Q4+T4+W4+Z4+AC4+AF4+AI4+AL4)/(C$48+E$48+H$48+K$48+N$48+Q$48+T$48+W$48+Z$48+AC$48+AF$48+AI$48+AL$48))*AL$54,AM4-((AM4/AM$48)*AL$52)+(AM4/AM$48)*AL$53+AO4+((C4+E4+H4+K4+N4+Q4+T4+W4+Z4+AC4+AF4+AI4+AL4)/(C$48+E$48+H$48+K$48+N$48+Q$48+T$48+W$48+Z$48+AC$48+AF$48+AI$48+AL$48))*AL$54) -> 1024519.3 | AQ4: =(AP4/AP$48)*AO$53 -> 0 | AR4: =epargne_mensuelle!S4 -> 0 | AS4: =IF(AP$48=0,AP4+AR4+((C4+E4+H4+K4+N4+Q4+T4+W4+Z4+AC4+AF4+AI4+AL4+AO4)/(C$48+E$48+H$48+K$48+N$48+Q$48+T$48+W$48+Z$48+AC$48+AF$48+AI$48+AL$48+AO$48))*AO$54,AP4-((AP4/AP$48)*AO$52)+(AP4/AP$48)*AO$53+AR4+((C4+E4+H4+K4+N4+Q4+T4+W4+Z4+AC4+AF4+AI4+AL4+AO4)/(C$48+E$48+H$48+K$48+N$48+Q$48+T$48+W$48+Z$48+AC$48+AF$48+AI$48+AL$48+AO$48))*AO$54) -> 1024519.3 | AT4: =(AS4/AS$48)*AR$53 -> 0 | AU4: =epargne_mensuelle!T4 -> 0 | AV4: =IF(AS$48=0,AS4+AU4+((C4+E4+H4+K4+N4+Q4+T4+W4+Z4+AC4+AF4+AI4+AL4+AO4+AR4)/(C$48+E$48+H$48+K$48+N$48+Q$48+T$48+W$48+Z$48+AC$48+AF$48+AI$48+AL$48+AO$48+AR$48))*AR$54,AS4-((AS4/AS$48)*AR$52)+(AS4/AS$48)*AR$53+AU4+((C4+E4+H4+K4+N4+Q4+T4+W4+Z4+AC4+AF4+AI4+AL4+AO4+AR4)/(C$48+E$48+H$48+K$48+N$48+Q$48+T$48+W$48+Z$48+AC$48+AF$48+AI$48+AL$48+AO$48+AR$48))*AR$54) -> 1024519.3 | AW4: =(AV4/AV$48)*AU$53 -> 0 | AX4: =epargne_mensuelle!U4 -> 0 | AY4: =IF(AV$48=0,AV4+AX4+((C4+E4+H4+K4+N4+Q4+T4+W4+Z4+AC4+AF4+AI4+AL4+AO4+AR4+AU4)/(C$48+E$48+H$48+K$48+N$48+Q$48+T$48+W$48+Z$48+AC$48+AF$48+AI$48+AL$48+AO$48+AR$48+AU$48))*AU$54,AV4-((AV4/AV$48)*AU$52)+(AV4/AV$48)*AU$53+AX4+((C4+E4+H4+K4+N4+Q4+T4+W4+Z4+AC4+AF4+AI4+AL4+AO4+AR4+AU4)/(C$48+E$48+H$48+K$48+N$48+Q$48+T$48+W$48+Z$48+AC$48+AF$48+AI$48+AL$48+AO$48+AR$48+AU$48))*AU$54) -> 1024519.3 | AZ4: =(AY4/AY$48)*AX$53 -> 0 | BA4: =epargne_mensuelle!V4 -> 0 | BB4: =IF(AY$48=0,AY4+BA4+((C4+E4+H4+K4+N4+Q4+T4+W4+Z4+AC4+AF4+AI4+AL4+AO4+AR4+AU4+AX4)/(C$48+E$48+H$48+K$48+N$48+Q$48+T$48+W$48+Z$48+AC$48+AF$48+AI$48+AL$48+AO$48+AR$48+AU$48+AX$48))*AX$54,AY4-((AY4/AY$48)*AX$52)+(AY4/AY$48)*AX$53+BA4+((C4+E4+H4+K4+N4+Q4+T4+W4+Z4+AC4+AF4+AI4+AL4+AO4+AR4+AU4+AX4)/(C$48+E$48+H$48+K$48+N$48+Q$48+T$48+W$48+Z$48+AC$48+AF$48+AI$48+AL$48+AO$48+AR$48+AU$48+AX$48))*AX$54) -> 1024519.3 | BC4: =(BB4/BB$48)*BA$53 -> 0 | BD4: =epargne_mensuelle!W4 -> 0 | BE4: =IF(BB$48=0,BB4+BD4+((C4+E4+H4+K4+N4+Q4+T4+W4+Z4+AC4+AF4+AI4+AL4+AO4+AR4+AU4+AX4+BA4)/(C$48+E$48+H$48+K$48+N$48+Q$48+T$48+W$48+Z$48+AC$48+AF$48+AI$48+AL$48+AO$48+AR$48+AU$48+AX$48+BA$48))*BA$54,BB4-((BB4/BB$48)*BA$52)+(BB4/BB$48)*BA$53+BD4+((C4+E4+H4+K4+N4+Q4+T4+W4+Z4+AC4+AF4+AI4+AL4+AO4+AR4+AU4+AX4+BA4)/(C$48+E$48+H$48+K$48+N$48+Q$48+T$48+W$48+Z$48+AC$48+AF$48+AI$48+AL$48+AO$48+AR$48+AU$48+AX$48+BA$48))*BA$54) -> 1024519.3 | BF4: =(BE4/BE$48)*BD$53 -> 0 | BG4: =epargne_mensuelle!X4 -> 0 | BH4: =IF(BE$48=0,BE4+BG4+((C4+E4+H4+K4+N4+Q4+T4+W4+Z4+AC4+AF4+AI4+AL4+AO4+AR4+AU4+AX4+BA4+BD4)/(C$48+E$48+H$48+K$48+N$48+Q$48+T$48+W$48+Z$48+AC$48+AF$48+AI$48+AL$48+AO$48+AR$48+AU$48+AX$48+BA$48+BD$48))*BD$54,BE4-((BE4/BE$48)*BD$52)+(BE4/BE$48)*BD$53+BG4+((C4+E4+H4+K4+N4+Q4+T4+W4+Z4+AC4+AF4+AI4+AL4+AO4+AR4+AU4+AX4+BA4+BD4)/(C$48+E$48+H$48+K$48+N$48+Q$48+T$48+W$48+Z$48+AC$48+AF$48+AI$48+AL$48+AO$48+AR$48+AU$48+AX$48+BA$48+BD$48))*BD$54) -> 1024519.3 | BI4: =(BH4/BH$48)*BG$53 -> 0 | BJ4: =epargne_mensuelle!Y4 -> 0 | BK4: =IF(BH$48=0,BH4+BJ4+((C4+E4+H4+K4+N4+Q4+T4+W4+Z4+AC4+AF4+AI4+AL4+AO4+AR4+AU4+AX4+BA4+BD4+BG4)/(C$48+E$48+H$48+K$48+N$48+Q$48+T$48+W$48+Z$48+AC$48+AF$48+AI$48+AL$48+AO$48+AR$48+AU$48+AX$48+BA$48+BD$48+BG$48))*BG$54,BH4-((BH4/BH$48)*BG$52)+(BH4/BH$48)*BG$53+BJ4+((C4+E4+H4+K4+N4+Q4+T4+W4+Z4+AC4+AF4+AI4+AL4+AO4+AR4+AU4+AX4+BA4+BD4+BG4)/(C$48+E$48+H$48+K$48+N$48+Q$48+T$48+W$48+Z$48+AC$48+AF$48+AI$48+AL$48+AO$48+AR$48+AU$48+AX$48+BA$48+BD$48+BG$48))*BG$54) -> 1024519.3 | BL4: =(BK4/BK$48)*BJ$53 -> 0 | BM4: =epargne_mensuelle!Z4 -> 0 | BN4: =IF(BK$48=0,BK4+BM4+((C4+E4+H4+K4+N4+Q4+T4+W4+Z4+AC4+AF4+AI4+AL4+AO4+AR4+AU4+AX4+BA4+BD4+BG4+BJ4)/(C$48+E$48+H$48+K$48+N$48+Q$48+T$48+W$48+Z$48+AC$48+AF$48+AI$48+AL$48+AO$48+AR$48+AU$48+AX$48+BA$48+BD$48+BG$48+BJ$48))*BJ$54,BK4-((BK4/BK$48)*BJ$52)+(BK4/BK$48)*BJ$53+BM4+((C4+E4+H4+K4+N4+Q4+T4+W4+Z4+AC4+AF4+AI4+AL4+AO4+AR4+AU4+AX4+BA4+BD4+BG4+BJ4)/(C$48+E$48+H$48+K$48+N$48+Q$48+T$48+W$48+Z$48+AC$48+AF$48+AI$48+AL$48+AO$48+AR$48+AU$48+AX$48+BA$48+BD$48+BG$48+BJ$48))*BJ$54) -> 1024519.3 | BO4: =(BN4/BN$48)*BM$53 -> 0 | BP4: =epargne_mensuelle!AA4 -> 0 | BQ4: =IF(BN$48=0,BN4+BP4+((F4+H4+K4+N4+Q4+T4+W4+Z4+AC4+AF4+AI4+AL4+AO4+AR4+AU4+AX4+BA4+BD4+BG4+BJ4+BM4)/(F$48+H$48+K$48+N$48+Q$48+T$48+W$48+Z$48+AC$48+AF$48+AI$48+AL$48+AO$48+AR$48+AU$48+AX$48+BA$48+BD$48+BG$48+BJ$48+BM$48))*BM$54,BN4-((BN4/BN$48)*BM$52)+(BN4/BN$48)*BM$53+BP4+((F4+H4+K4+N4+Q4+T4+W4+Z4+AC4+AF4+AI4+AL4+AO4+AR4+AU4+AX4+BA4+BD4+BG4+BJ4+BM4)/(F$48+H$48+K$48+N$48+Q$48+T$48+W$48+Z$48+AC$48+AF$48+AI$48+AL$48+AO$48+AR$48+AU$48+AX$48+BA$48+BD$48+BG$48+BJ$48+BM$48))*BM$54) -> 1024519.3 | BR4: =(BQ4/BQ$48)*BP$53 -> 0 | BS4: =epargne_mensuelle!AB4 -> 0 | BT4: =IF(BQ$48=0,BQ4+BS4+((I4+K4+N4+Q4+T4+W4+Z4+AC4+AF4+AI4+AL4+AO4+AR4+AU4+AX4+BA4+BD4+BG4+BJ4+BM4+BP4)/(I$48+K$48+N$48+Q$48+T$48+W$48+Z$48+AC$48+AF$48+AI$48+AL$48+AO$48+AR$48+AU$48+AX$48+BA$48+BD$48+BG$48+BJ$48+BM$48+BP$48))*BP$54,BQ4-((BQ4/BQ$48)*BP$52)+(BQ4/BQ$48)*BP$53+BS4+((I4+K4+N4+Q4+T4+W4+Z4+AC4+AF4+AI4+AL4+AO4+AR4+AU4+AX4+BA4+BD4+BG4+BJ4+BM4+BP4)/(I$48+K$48+N$48+Q$48+T$48+W$48+Z$48+AC$48+AF$48+AI$48+AL$48+AO$48+AR$48+AU$48+AX$48+BA$48+BD$48+BG$48+BJ$48+BM$48+BP$48))*BP$54) -> 1024519.3 | BU4: =(BT4/BT$48)*BS$53 -> 0 | BV4: =cumul_epargne!C4 -> 4008079.8 | BW4: =D4+G4+J4+M4+P4+S4+V4+Y4+AB4+AE4+AH4+AK4+AN4+AQ4+AT4+AW4+AZ4+BC4+BF4+BI4+BL4+BO4+BR4+BU4 -> 667719.35 | BX4: =IF(BV4="",BW4,BV4+BW4) -> 4675799.1 | BZ4: =BX4+BY4 -> 4675799.1 | CA4: =IF(BV4="","",BW4/BV4) -> 0.16659333 | CB4: =BZ4/BZ$48 -> 0.10306653 | CC4: =CB4*(C$50-BW$58-BW$57) -> 446154.72 | CD4: =B4 -> ACTIONNIRE3
A5: =epargne_mensuelle!A5 -> 4 | B5: =epargne_mensuelle!B5 -> ACTIONNIRE4 | C5: =SUM(epargne_mensuelle!C5:E5) -> 372369.77 | D5: =(C5/C$48)*C$53 -> 47067.593 | E5: =epargne_mensuelle!F5 -> 0 | F5: =C5-(C5/C$48)*C$52+(C5/C$48)*C$53+E5+(C5/C$48)*C$54 -> 55748.018 | G5: =(F5/F$48)*E$53 -> 0 | H5: =epargne_mensuelle!G5 -> 0 | I5: =IF(F$48=0,F5+H5+((C5+E5)/(C$48+E$48))*E$54,F5-((F5/F$48)*E$52)+(F5/F$48)*E$53+H5+((C5+E5)/(C$48+E$48))*E$54) -> 63515.607 | J5: =(I5/I$48)*H$53 -> 6034.8049 | K5: =epargne_mensuelle!H5 -> 0 | L5: =IF(I$48=0,I5+K5+((C5+E5+H5)/(C$48+E$48+H$48))*H$54,I5-((I5/I$48)*H$52)+(I5/I$48)*H$53+K5+((C5+E5+H5)/(C$48+E$48+H$48))*H$54) -> 54051.492 | M5: =(L5/L$48)*K$53 -> 2091.6244 | N5: =epargne_mensuelle!I5 -> 0 | O5: =IF(L$48=0,L5+N5+((C5+E5+H5+K5)/(C$48+E$48+H$48+K$48))*K$54,L5-((L5/L$48)*K$52)+(L5/L$48)*K$53+N5+((C5+E5+H5+K5)/(C$48+E$48+H$48+K$48))*K$54) -> 47362.631 | P5: =(O5/O$48)*N$53 -> 748.83962 | Q5: =epargne_mensuelle!J5 -> 0 | R5: =IF(O$48=0,O5+Q5+((C5+E5+H5+K5+N5)/(C$48+E$48+H$48+K$48+N$48))*N$54,O5-((O5/O$48)*N$52)+(O5/O$48)*N$53+Q5+((C5+E5+H5+K5+N5)/(C$48+E$48+H$48+K$48+N$48))*N$54) -> 73303.087 | S5: =(R5/R$48)*Q$53 -> 6091.4563 | T5: =epargne_mensuelle!K5 -> 0 | U5: =IF(R$48=0,R5+T5+((C5+E5+H5+K5+N5+Q5)/(C$48+E$48+H$48+K$48+N$48+Q$48))*Q$54,R5-((R5/R$48)*Q$52)+(R5/R$48)*Q$53+T5+((C5+E5+H5+K5+N5+Q5)/(C$48+E$48+H$48+K$48+N$48+Q$48))*Q$54) -> 95182.74 | V5: =(U5/U$48)*T$53 -> 0 | W5: =epargne_mensuelle!L5 -> 0 | X5: =IF(U$48=0,U5+W5+((C5+E5+H5+K5+N5+Q5+T5)/(C$48+E$48+H$48+K$48+N$48+Q$48+T$48))*T$54,U5-((U5/U$48)*T$52)+(U5/U$48)*T$53+W5+((C5+E5+H5+K5+N5+Q5+T5)/(C$48+E$48+H$48+K$48+N$48+Q$48+T$48))*T$54) -> 95182.74 | Y5: =(X5/X$48)*W$53 -> 0 | Z5: =epargne_mensuelle!M5 -> 0 | AA5: =IF(X$48=0,X5+Z5+((C5+E5+H5+K5+N5+Q5+T5+W5)/(C$48+E$48+H$48+K$48+N$48+Q$48+T$48+W$48))*W$54,X5-((X5/X$48)*W$52)+(X5/X$48)*W$53+Z5+((C5+E5+H5+K5+N5+Q5+T5+W5)/(C$48+E$48+H$48+K$48+N$48+Q$48+T$48+W$48))*W$54) -> 95182.74 | AB5: =(AA5/AA$48)*Z$53 -> 0 | AC5: =epargne_mensuelle!N5 -> 0 | AD5: =IF(AA$48=0,AA5+AC5+((C5+E5+H5+K5+N5+Q5+T5+W5+Z5)/(C$48+E$48+H$48+K$48+N$48+Q$48+T$48+W$48+Z$48))*Z$54,AA5-((AA5/AA$48)*Z$52)+(AA5/AA$48)*Z$53+AC5+((C5+E5+H5+K5+N5+Q5+T5+W5+Z5)/(C$48+E$48+H$48+K$48+N$48+Q$48+T$48+W$48+Z$48))*Z$54) -> 95182.74 | AE5: =(AD5/AD$48)*AC$53 -> 0 | AF5: =epargne_mensuelle!O5 -> 0 | AG5: =IF(AD$48=0,AD5+AF5+((C5+E5+H5+K5+N5+Q5+T5+W5+Z5+AC5)/(C$48+E$48+H$48+K$48+N$48+Q$48+T$48+W$48+Z$48+AC$48))*AC$54,AD5-((AD5/AD$48)*AC$52)+(AD5/AD$48)*AC$53+AF5+((C5+E5+H5+K5+N5+Q5+T5+W5+Z5+AC5)/(C$48+E$48+H$48+K$48+N$48+Q$48+T$48+W$48+Z$48+AC$48))*AC$54) -> 95182.74 | AH5: =(AG5/AG$48)*AF$53 -> 0 | AI5: =epargne_mensuelle!P5 -> 0 | AJ5: =IF(AG$48=0,AG5+AI5+((C5+E5+H5+K5+N5+Q5+T5+W5+Z5+AC5+AF5)/(C$48+E$48+H$48+K$48+N$48+Q$48+T$48+W$48+Z$48+AC$48+AF$48))*AF$54,AG5-((AG5/AG$48)*AF$52)+(AG5/AG$48)*AF$53+AI5+((C5+E5+H5+K5+N5+Q5+T5+W5+Z5+AC5+AF5)/(C$48+E$48+H$48+K$48+N$48+Q$48+T$48+W$48+Z$48+AC$48+AF$48))*AF$54) -> 95182.74 | AK5: =(AJ5/AJ$48)*AI$53 -> 0 | AL5: =epargne_mensuelle!Q5 -> 0 | AM5: =IF(AJ$48=0,AJ5+AL5+((C5+E5+H5+K5+N5+Q5+T5+W5+Z5+AC5+AF5+AI5)/(C$48+E$48+H$48+K$48+N$48+Q$48+T$48+W$48+Z$48+AC$48+AF$48+AI$48))*AI$54,AJ5-((AJ5/AJ$48)*AI$52)+(AJ5/AJ$48)*AI$53+AL5+((C5+E5+H5+K5+N5+Q5+T5+W5+Z5+AC5+AF5+AI5)/(C$48+E$48+H$48+K$48+N$48+Q$48+T$48+W$48+Z$48+AC$48+AF$48+AI$48))*AI$54) -> 95182.74 | AN5: =(AM5/AM$48)*AL$53 -> 0 | AO5: =epargne_mensuelle!R5 -> 0 | AP5: =IF(AM$48=0,AM5+AO5+((C5+E5+H5+K5+N5+Q5+T5+W5+Z5+AC5+AF5+AI5+AL5)/(C$48+E$48+H$48+K$48+N$48+Q$48+T$48+W$48+Z$48+AC$48+AF$48+AI$48+AL$48))*AL$54,AM5-((AM5/AM$48)*AL$52)+(AM5/AM$48)*AL$53+AO5+((C5+E5+H5+K5+N5+Q5+T5+W5+Z5+AC5+AF5+AI5+AL5)/(C$48+E$48+H$48+K$48+N$48+Q$48+T$48+W$48+Z$48+AC$48+AF$48+AI$48+AL$48))*AL$54) -> 95182.74 | AQ5: =(AP5/AP$48)*AO$53 -> 0 | AR5: =epargne_mensuelle!S5 -> 0 | AS5: =IF(AP$48=0,AP5+AR5+((C5+E5+H5+K5+N5+Q5+T5+W5+Z5+AC5+AF5+AI5+AL5+AO5)/(C$48+E$48+H$48+K$48+N$48+Q$48+T$48+W$48+Z$48+AC$48+AF$48+AI$48+AL$48+AO$48))*AO$54,AP5-((AP5/AP$48)*AO$52)+(AP5/AP$48)*AO$53+AR5+((C5+E5+H5+K5+N5+Q5+T5+W5+Z5+AC5+AF5+AI5+AL5+AO5)/(C$48+E$48+H$48+K$48+N$48+Q$48+T$48+W$48+Z$48+AC$48+AF$48+AI$48+AL$48+AO$48))*AO$54) -> 95182.74 | AT5: =(AS5/AS$48)*AR$53 -> 0 | AU5: =epargne_mensuelle!T5 -> 0 | AV5: =IF(AS$48=0,AS5+AU5+((C5+E5+H5+K5+N5+Q5+T5+W5+Z5+AC5+AF5+AI5+AL5+AO5+AR5)/(C$48+E$48+H$48+K$48+N$48+Q$48+T$48+W$48+Z$48+AC$48+AF$48+AI$48+AL$48+AO$48+AR$48))*AR$54,AS5-((AS5/AS$48)*AR$52)+(AS5/AS$48)*AR$53+AU5+((C5+E5+H5+K5+N5+Q5+T5+W5+Z5+AC5+AF5+AI5+AL5+AO5+AR5)/(C$48+E$48+H$48+K$48+N$48+Q$48+T$48+W$48+Z$48+AC$48+AF$48+AI$48+AL$48+AO$48+AR$48))*AR$54) -> 95182.74 | AW5: =(AV5/AV$48)*AU$53 -> 0 | AX5: =epargne_mensuelle!U5 -> 0 | AY5: =IF(AV$48=0,AV5+AX5+((C5+E5+H5+K5+N5+Q5+T5+W5+Z5+AC5+AF5+AI5+AL5+AO5+AR5+AU5)/(C$48+E$48+H$48+K$48+N$48+Q$48+T$48+W$48+Z$48+AC$48+AF$48+AI$48+AL$48+AO$48+AR$48+AU$48))*AU$54,AV5-((AV5/AV$48)*AU$52)+(AV5/AV$48)*AU$53+AX5+((C5+E5+H5+K5+N5+Q5+T5+W5+Z5+AC5+AF5+AI5+AL5+AO5+AR5+AU5)/(C$48+E$48+H$48+K$48+N$48+Q$48+T$48+W$48+Z$48+AC$48+AF$48+AI$48+AL$48+AO$48+AR$48+AU$48))*AU$54) -> 95182.74 | AZ5: =(AY5/AY$48)*AX$53 -> 0 | BA5: =epargne_mensuelle!V5 -> 0 | BB5: =IF(AY$48=0,AY5+BA5+((C5+E5+H5+K5+N5+Q5+T5+W5+Z5+AC5+AF5+AI5+AL5+AO5+AR5+AU5+AX5)/(C$48+E$48+H$48+K$48+N$48+Q$48+T$48+W$48+Z$48+AC$48+AF$48+AI$48+AL$48+AO$48+AR$48+AU$48+AX$48))*AX$54,AY5-((AY5/AY$48)*AX$52)+(AY5/AY$48)*AX$53+BA5+((C5+E5+H5+K5+N5+Q5+T5+W5+Z5+AC5+AF5+AI5+AL5+AO5+AR5+AU5+AX5)/(C$48+E$48+H$48+K$48+N$48+Q$48+T$48+W$48+Z$48+AC$48+AF$48+AI$48+AL$48+AO$48+AR$48+AU$48+AX$48))*AX$54) -> 95182.74 | BC5: =(BB5/BB$48)*BA$53 -> 0 | BD5: =epargne_mensuelle!W5 -> 0 | BE5: =IF(BB$48=0,BB5+BD5+((C5+E5+H5+K5+N5+Q5+T5+W5+Z5+AC5+AF5+AI5+AL5+AO5+AR5+AU5+AX5+BA5)/(C$48+E$48+H$48+K$48+N$48+Q$48+T$48+W$48+Z$48+AC$48+AF$48+AI$48+AL$48+AO$48+AR$48+AU$48+AX$48+BA$48))*BA$54,BB5-((BB5/BB$48)*BA$52)+(BB5/BB$48)*BA$53+BD5+((C5+E5+H5+K5+N5+Q5+T5+W5+Z5+AC5+AF5+AI5+AL5+AO5+AR5+AU5+AX5+BA5)/(C$48+E$48+H$48+K$48+N$48+Q$48+T$48+W$48+Z$48+AC$48+AF$48+AI$48+AL$48+AO$48+AR$48+AU$48+AX$48+BA$48))*BA$54) -> 95182.74 | BF5: =(BE5/BE$48)*BD$53 -> 0 | BG5: =epargne_mensuelle!X5 -> 0 | BH5: =IF(BE$48=0,BE5+BG5+((C5+E5+H5+K5+N5+Q5+T5+W5+Z5+AC5+AF5+AI5+AL5+AO5+AR5+AU5+AX5+BA5+BD5)/(C$48+E$48+H$48+K$48+N$48+Q$48+T$48+W$48+Z$48+AC$48+AF$48+AI$48+AL$48+AO$48+AR$48+AU$48+AX$48+BA$48+BD$48))*BD$54,BE5-((BE5/BE$48)*BD$52)+(BE5/BE$48)*BD$53+BG5+((C5+E5+H5+K5+N5+Q5+T5+W5+Z5+AC5+AF5+AI5+AL5+AO5+AR5+AU5+AX5+BA5+BD5)/(C$48+E$48+H$48+K$48+N$48+Q$48+T$48+W$48+Z$48+AC$48+AF$48+AI$48+AL$48+AO$48+AR$48+AU$48+AX$48+BA$48+BD$48))*BD$54) -> 95182.74 | BI5: =(BH5/BH$48)*BG$53 -> 0 | BJ5: =epargne_mensuelle!Y5 -> 0 | BK5: =IF(BH$48=0,BH5+BJ5+((C5+E5+H5+K5+N5+Q5+T5+W5+Z5+AC5+AF5+AI5+AL5+AO5+AR5+AU5+AX5+BA5+BD5+BG5)/(C$48+E$48+H$48+K$48+N$48+Q$48+T$48+W$48+Z$48+AC$48+AF$48+AI$48+AL$48+AO$48+AR$48+AU$48+AX$48+BA$48+BD$48+BG$48))*BG$54,BH5-((BH5/BH$48)*BG$52)+(BH5/BH$48)*BG$53+BJ5+((C5+E5+H5+K5+N5+Q5+T5+W5+Z5+AC5+AF5+AI5+AL5+AO5+AR5+AU5+AX5+BA5+BD5+BG5)/(C$48+E$48+H$48+K$48+N$48+Q$48+T$48+W$48+Z$48+AC$48+AF$48+AI$48+AL$48+AO$48+AR$48+AU$48+AX$48+BA$48+BD$48+BG$48))*BG$54) -> 95182.74 | BL5: =(BK5/BK$48)*BJ$53 -> 0 | BM5: =epargne_mensuelle!Z5 -> 0 | BN5: =IF(BK$48=0,BK5+BM5+((C5+E5+H5+K5+N5+Q5+T5+W5+Z5+AC5+AF5+AI5+AL5+AO5+AR5+AU5+AX5+BA5+BD5+BG5+BJ5)/(C$48+E$48+H$48+K$48+N$48+Q$48+T$48+W$48+Z$48+AC$48+AF$48+AI$48+AL$48+AO$48+AR$48+AU$48+AX$48+BA$48+BD$48+BG$48+BJ$48))*BJ$54,BK5-((BK5/BK$48)*BJ$52)+(BK5/BK$48)*BJ$53+BM5+((C5+E5+H5+K5+N5+Q5+T5+W5+Z5+AC5+AF5+AI5+AL5+AO5+AR5+AU5+AX5+BA5+BD5+BG5+BJ5)/(C$48+E$48+H$48+K$48+N$48+Q$48+T$48+W$48+Z$48+AC$48+AF$48+AI$48+AL$48+AO$48+AR$48+AU$48+AX$48+BA$48+BD$48+BG$48+BJ$48))*BJ$54) -> 95182.74 | BO5: =(BN5/BN$48)*BM$53 -> 0 | BP5: =epargne_mensuelle!AA5 -> 0 | BQ5: =IF(BN$48=0,BN5+BP5+((F5+H5+K5+N5+Q5+T5+W5+Z5+AC5+AF5+AI5+AL5+AO5+AR5+AU5+AX5+BA5+BD5+BG5+BJ5+BM5)/(F$48+H$48+K$48+N$48+Q$48+T$48+W$48+Z$48+AC$48+AF$48+AI$48+AL$48+AO$48+AR$48+AU$48+AX$48+BA$48+BD$48+BG$48+BJ$48+BM$48))*BM$54,BN5-((BN5/BN$48)*BM$52)+(BN5/BN$48)*BM$53+BP5+((F5+H5+K5+N5+Q5+T5+W5+Z5+AC5+AF5+AI5+AL5+AO5+AR5+AU5+AX5+BA5+BD5+BG5+BJ5+BM5)/(F$48+H$48+K$48+N$48+Q$48+T$48+W$48+Z$48+AC$48+AF$48+AI$48+AL$48+AO$48+AR$48+AU$48+AX$48+BA$48+BD$48+BG$48+BJ$48+BM$48))*BM$54) -> 95182.74 | BR5: =(BQ5/BQ$48)*BP$53 -> 0 | BS5: =epargne_mensuelle!AB5 -> 0 | BT5: =IF(BQ$48=0,BQ5+BS5+((I5+K5+N5+Q5+T5+W5+Z5+AC5+AF5+AI5+AL5+AO5+AR5+AU5+AX5+BA5+BD5+BG5+BJ5+BM5+BP5)/(I$48+K$48+N$48+Q$48+T$48+W$48+Z$48+AC$48+AF$48+AI$48+AL$48+AO$48+AR$48+AU$48+AX$48+BA$48+BD$48+BG$48+BJ$48+BM$48+BP$48))*BP$54,BQ5-((BQ5/BQ$48)*BP$52)+(BQ5/BQ$48)*BP$53+BS5+((I5+K5+N5+Q5+T5+W5+Z5+AC5+AF5+AI5+AL5+AO5+AR5+AU5+AX5+BA5+BD5+BG5+BJ5+BM5+BP5)/(I$48+K$48+N$48+Q$48+T$48+W$48+Z$48+AC$48+AF$48+AI$48+AL$48+AO$48+AR$48+AU$48+AX$48+BA$48+BD$48+BG$48+BJ$48+BM$48+BP$48))*BP$54) -> 95182.74 | BU5: =(BT5/BT$48)*BS$53 -> 0 | BV5: =cumul_epargne!C5 -> 372369.77 | BW5: =D5+G5+J5+M5+P5+S5+V5+Y5+AB5+AE5+AH5+AK5+AN5+AQ5+AT5+AW5+AZ5+BC5+BF5+BI5+BL5+BO5+BR5+BU5 -> 62034.319 | BX5: =IF(BV5="",BW5,BV5+BW5) -> 434404.08 | BZ5: =BX5+BY5 -> 434404.08 | CA5: =IF(BV5="","",BW5/BV5) -> 0.16659333 | CB5: =BZ5/BZ$48 -> 0.0095753735 | CC5: =CB5*(C$50-BW$58-BW$57) -> 41449.905 | CD5: =B5 -> ACTIONNIRE4
A6: =epargne_mensuelle!A6 -> 5 | B6: =epargne_mensuelle!B6 -> ACTIONNIRE5 | C6: =SUM(epargne_mensuelle!C6:E6) -> 1393753.8 | D6: =(C6/C$48)*C$53 -> 176170.69 | E6: =epargne_mensuelle!F6 -> 0 | F6: =C6-(C6/C$48)*C$52+(C6/C$48)*C$53+E6+(C6/C$48)*C$54 -> 208660.91 | G6: =(F6/F$48)*E$53 -> 0 | H6: =epargne_mensuelle!G6 -> 0 | I6: =IF(F$48=0,F6+H6+((C6+E6)/(C$48+E$48))*E$54,F6-((F6/F$48)*E$52)+(F6/F$48)*E$53+H6+((C6+E6)/(C$48+E$48))*E$54) -> 237734.45 | J6: =(I6/I$48)*H$53 -> 22587.85 | K6: =epargne_mensuelle!H6 -> 0 | L6: =IF(I$48=0,I6+K6+((C6+E6+H6)/(C$48+E$48+H$48))*H$54,I6-((I6/I$48)*H$52)+(I6/I$48)*H$53+K6+((C6+E6+H6)/(C$48+E$48+H$48))*H$54) -> 202310.93 | M6: =(L6/L$48)*K$53 -> 7828.803 | N6: =epargne_mensuelle!I6 -> 0 | O6: =IF(L$48=0,L6+N6+((C6+E6+H6+K6)/(C$48+E$48+H$48+K$48))*K$54,L6-((L6/L$48)*K$52)+(L6/L$48)*K$53+N6+((C6+E6+H6+K6)/(C$48+E$48+H$48+K$48))*K$54) -> 177274.99 | P6: =(O6/O$48)*N$53 -> 2802.854 | Q6: =epargne_mensuelle!J6 -> 0 | R6: =IF(O$48=0,O6+Q6+((C6+E6+H6+K6+N6)/(C$48+E$48+H$48+K$48+N$48))*N$54,O6-((O6/O$48)*N$52)+(O6/O$48)*N$53+Q6+((C6+E6+H6+K6+N6)/(C$48+E$48+H$48+K$48+N$48))*N$54) -> 274368.3 | S6: =(R6/R$48)*Q$53 -> 22799.892 | T6: =epargne_mensuelle!K6 -> 0 | U6: =IF(R$48=0,R6+T6+((C6+E6+H6+K6+N6+Q6)/(C$48+E$48+H$48+K$48+N$48+Q$48))*Q$54,R6-((R6/R$48)*Q$52)+(R6/R$48)*Q$53+T6+((C6+E6+H6+K6+N6+Q6)/(C$48+E$48+H$48+K$48+N$48+Q$48))*Q$54) -> 356262.3 | V6: =(U6/U$48)*T$53 -> 0 | W6: =epargne_mensuelle!L6 -> 0 | X6: =IF(U$48=0,U6+W6+((C6+E6+H6+K6+N6+Q6+T6)/(C$48+E$48+H$48+K$48+N$48+Q$48+T$48))*T$54,U6-((U6/U$48)*T$52)+(U6/U$48)*T$53+W6+((C6+E6+H6+K6+N6+Q6+T6)/(C$48+E$48+H$48+K$48+N$48+Q$48+T$48))*T$54) -> 356262.3 | Y6: =(X6/X$48)*W$53 -> 0 | Z6: =epargne_mensuelle!M6 -> 0 | AA6: =IF(X$48=0,X6+Z6+((C6+E6+H6+K6+N6+Q6+T6+W6)/(C$48+E$48+H$48+K$48+N$48+Q$48+T$48+W$48))*W$54,X6-((X6/X$48)*W$52)+(X6/X$48)*W$53+Z6+((C6+E6+H6+K6+N6+Q6+T6+W6)/(C$48+E$48+H$48+K$48+N$48+Q$48+T$48+W$48))*W$54) -> 356262.3 | AB6: =(AA6/AA$48)*Z$53 -> 0 | AC6: =epargne_mensuelle!N6 -> 0 | AD6: =IF(AA$48=0,AA6+AC6+((C6+E6+H6+K6+N6+Q6+T6+W6+Z6)/(C$48+E$48+H$48+K$48+N$48+Q$48+T$48+W$48+Z$48))*Z$54,AA6-((AA6/AA$48)*Z$52)+(AA6/AA$48)*Z$53+AC6+((C6+E6+H6+K6+N6+Q6+T6+W6+Z6)/(C$48+E$48+H$48+K$48+N$48+Q$48+T$48+W$48+Z$48))*Z$54) -> 356262.3 | AE6: =(AD6/AD$48)*AC$53 -> 0 | AF6: =epargne_mensuelle!O6 -> 0 | AG6: =IF(AD$48=0,AD6+AF6+((C6+E6+H6+K6+N6+Q6+T6+W6+Z6+AC6)/(C$48+E$48+H$48+K$48+N$48+Q$48+T$48+W$48+Z$48+AC$48))*AC$54,AD6-((AD6/AD$48)*AC$52)+(AD6/AD$48)*AC$53+AF6+((C6+E6+H6+K6+N6+Q6+T6+W6+Z6+AC6)/(C$48+E$48+H$48+K$48+N$48+Q$48+T$48+W$48+Z$48+AC$48))*AC$54) -> 356262.3 | AH6: =(AG6/AG$48)*AF$53 -> 0 | AI6: =epargne_mensuelle!P6 -> 0 | AJ6: =IF(AG$48=0,AG6+AI6+((C6+E6+H6+K6+N6+Q6+T6+W6+Z6+AC6+AF6)/(C$48+E$48+H$48+K$48+N$48+Q$48+T$48+W$48+Z$48+AC$48+AF$48))*AF$54,AG6-((AG6/AG$48)*AF$52)+(AG6/AG$48)*AF$53+AI6+((C6+E6+H6+K6+N6+Q6+T6+W6+Z6+AC6+AF6)/(C$48+E$48+H$48+K$48+N$48+Q$48+T$48+W$48+Z$48+AC$48+AF$48))*AF$54) -> 356262.3 | AK6: =(AJ6/AJ$48)*AI$53 -> 0 | AL6: =epargne_mensuelle!Q6 -> 0 | AM6: =IF(AJ$48=0,AJ6+AL6+((C6+E6+H6+K6+N6+Q6+T6+W6+Z6+AC6+AF6+AI6)/(C$48+E$48+H$48+K$48+N$48+Q$48+T$48+W$48+Z$48+AC$48+AF$48+AI$48))*AI$54,AJ6-((AJ6/AJ$48)*AI$52)+(AJ6/AJ$48)*AI$53+AL6+((C6+E6+H6+K6+N6+Q6+T6+W6+Z6+AC6+AF6+AI6)/(C$48+E$48+H$48+K$48+N$48+Q$48+T$48+W$48+Z$48+AC$48+AF$48+AI$48))*AI$54) -> 356262.3 | AN6: =(AM6/AM$48)*AL$53 -> 0 | AO6: =epargne_mensuelle!R6 -> 0 | AP6: =IF(AM$48=0,AM6+AO6+((C6+E6+H6+K6+N6+Q6+T6+W6+Z6+AC6+AF6+AI6+AL6)/(C$48+E$48+H$48+K$48+N$48+Q$48+T$48+W$48+Z$48+AC$48+AF$48+AI$48+AL$48))*AL$54,AM6-((AM6/AM$48)*AL$52)+(AM6/AM$48)*AL$53+AO6+((C6+E6+H6+K6+N6+Q6+T6+W6+Z6+AC6+AF6+AI6+AL6)/(C$48+E$48+H$48+K$48+N$48+Q$48+T$48+W$48+Z$48+AC$48+AF$48+AI$48+AL$48))*AL$54) -> 356262.3 | AQ6: =(AP6/AP$48)*AO$53 -> 0 | AR6: =epargne_mensuelle!S6 -> 0 | AS6: =IF(AP$48=0,AP6+AR6+((C6+E6+H6+K6+N6+Q6+T6+W6+Z6+AC6+AF6+AI6+AL6+AO6)/(C$48+E$48+H$48+K$48+N$48+Q$48+T$48+W$48+Z$48+AC$48+AF$48+AI$48+AL$48+AO$48))*AO$54,AP6-((AP6/AP$48)*AO$52)+(AP6/AP$48)*AO$53+AR6+((C6+E6+H6+K6+N6+Q6+T6+W6+Z6+AC6+AF6+AI6+AL6+AO6)/(C$48+E$48+H$48+K$48+N$48+Q$48+T$48+W$48+Z$48+AC$48+AF$48+AI$48+AL$48+AO$48))*AO$54) -> 356262.3 | AT6: =(AS6/AS$48)*AR$53 -> 0 | AU6: =epargne_mensuelle!T6 -> 0 | AV6: =IF(AS$48=0,AS6+AU6+((C6+E6+H6+K6+N6+Q6+T6+W6+Z6+AC6+AF6+AI6+AL6+AO6+AR6)/(C$48+E$48+H$48+K$48+N$48+Q$48+T$48+W$48+Z$48+AC$48+AF$48+AI$48+AL$48+AO$48+AR$48))*AR$54,AS6-((AS6/AS$48)*AR$52)+(AS6/AS$48)*AR$53+AU6+((C6+E6+H6+K6+N6+Q6+T6+W6+Z6+AC6+AF6+AI6+AL6+AO6+AR6)/(C$48+E$48+H$48+K$48+N$48+Q$48+T$48+W$48+Z$48+AC$48+AF$48+AI$48+AL$48+AO$48+AR$48))*AR$54) -> 356262.3 | AW6: =(AV6/AV$48)*AU$53 -> 0 | AX6: =epargne_mensuelle!U6 -> 0 | AY6: =IF(AV$48=0,AV6+AX6+((C6+E6+H6+K6+N6+Q6+T6+W6+Z6+AC6+AF6+AI6+AL6+AO6+AR6+AU6)/(C$48+E$48+H$48+K$48+N$48+Q$48+T$48+W$48+Z$48+AC$48+AF$48+AI$48+AL$48+AO$48+AR$48+AU$48))*AU$54,AV6-((AV6/AV$48)*AU$52)+(AV6/AV$48)*AU$53+AX6+((C6+E6+H6+K6+N6+Q6+T6+W6+Z6+AC6+AF6+AI6+AL6+AO6+AR6+AU6)/(C$48+E$48+H$48+K$48+N$48+Q$48+T$48+W$48+Z$48+AC$48+AF$48+AI$48+AL$48+AO$48+AR$48+AU$48))*AU$54) -> 356262.3 | AZ6: =(AY6/AY$48)*AX$53 -> 0 | BA6: =epargne_mensuelle!V6 -> 0 | BB6: =IF(AY$48=0,AY6+BA6+((C6+E6+H6+K6+N6+Q6+T6+W6+Z6+AC6+AF6+AI6+AL6+AO6+AR6+AU6+AX6)/(C$48+E$48+H$48+K$48+N$48+Q$48+T$48+W$48+Z$48+AC$48+AF$48+AI$48+AL$48+AO$48+AR$48+AU$48+AX$48))*AX$54,AY6-((AY6/AY$48)*AX$52)+(AY6/AY$48)*AX$53+BA6+((C6+E6+H6+K6+N6+Q6+T6+W6+Z6+AC6+AF6+AI6+AL6+AO6+AR6+AU6+AX6)/(C$48+E$48+H$48+K$48+N$48+Q$48+T$48+W$48+Z$48+AC$48+AF$48+AI$48+AL$48+AO$48+AR$48+AU$48+AX$48))*AX$54) -> 356262.3 | BC6: =(BB6/BB$48)*BA$53 -> 0 | BD6: =epargne_mensuelle!W6 -> 0 | BE6: =IF(BB$48=0,BB6+BD6+((C6+E6+H6+K6+N6+Q6+T6+W6+Z6+AC6+AF6+AI6+AL6+AO6+AR6+AU6+AX6+BA6)/(C$48+E$48+H$48+K$48+N$48+Q$48+T$48+W$48+Z$48+AC$48+AF$48+AI$48+AL$48+AO$48+AR$48+AU$48+AX$48+BA$48))*BA$54,BB6-((BB6/BB$48)*BA$52)+(BB6/BB$48)*BA$53+BD6+((C6+E6+H6+K6+N6+Q6+T6+W6+Z6+AC6+AF6+AI6+AL6+AO6+AR6+AU6+AX6+BA6)/(C$48+E$48+H$48+K$48+N$48+Q$48+T$48+W$48+Z$48+AC$48+AF$48+AI$48+AL$48+AO$48+AR$48+AU$48+AX$48+BA$48))*BA$54) -> 356262.3 | BF6: =(BE6/BE$48)*BD$53 -> 0 | BG6: =epargne_mensuelle!X6 -> 0 | BH6: =IF(BE$48=0,BE6+BG6+((C6+E6+H6+K6+N6+Q6+T6+W6+Z6+AC6+AF6+AI6+AL6+AO6+AR6+AU6+AX6+BA6+BD6)/(C$48+E$48+H$48+K$48+N$48+Q$48+T$48+W$48+Z$48+AC$48+AF$48+AI$48+AL$48+AO$48+AR$48+AU$48+AX$48+BA$48+BD$48))*BD$54,BE6-((BE6/BE$48)*BD$52)+(BE6/BE$48)*BD$53+BG6+((C6+E6+H6+K6+N6+Q6+T6+W6+Z6+AC6+AF6+AI6+AL6+AO6+AR6+AU6+AX6+BA6+BD6)/(C$48+E$48+H$48+K$48+N$48+Q$48+T$48+W$48+Z$48+AC$48+AF$48+AI$48+AL$48+AO$48+AR$48+AU$48+AX$48+BA$48+BD$48))*BD$54) -> 356262.3 | BI6: =(BH6/BH$48)*BG$53 -> 0 | BJ6: =epargne_mensuelle!Y6 -> 0 | BK6: =IF(BH$48=0,BH6+BJ6+((C6+E6+H6+K6+N6+Q6+T6+W6+Z6+AC6+AF6+AI6+AL6+AO6+AR6+AU6+AX6+BA6+BD6+BG6)/(C$48+E$48+H$48+K$48+N$48+Q$48+T$48+W$48+Z$48+AC$48+AF$48+AI$48+AL$48+AO$48+AR$48+AU$48+AX$48+BA$48+BD$48+BG$48))*BG$54,BH6-((BH6/BH$48)*BG$52)+(BH6/BH$48)*BG$53+BJ6+((C6+E6+H6+K6+N6+Q6+T6+W6+Z6+AC6+AF6+AI6+AL6+AO6+AR6+AU6+AX6+BA6+BD6+BG6)/(C$48+E$48+H$48+K$48+N$48+Q$48+T$48+W$48+Z$48+AC$48+AF$48+AI$48+AL$48+AO$48+AR$48+AU$48+AX$48+BA$48+BD$48+BG$48))*BG$54) -> 356262.3 | BL6: =(BK6/BK$48)*BJ$53 -> 0 | BM6: =epargne_mensuelle!Z6 -> 0 | BN6: =IF(BK$48=0,BK6+BM6+((C6+E6+H6+K6+N6+Q6+T6+W6+Z6+AC6+AF6+AI6+AL6+AO6+AR6+AU6+AX6+BA6+BD6+BG6+BJ6)/(C$48+E$48+H$48+K$48+N$48+Q$48+T$48+W$48+Z$48+AC$48+AF$48+AI$48+AL$48+AO$48+AR$48+AU$48+AX$48+BA$48+BD$48+BG$48+BJ$48))*BJ$54,BK6-((BK6/BK$48)*BJ$52)+(BK6/BK$48)*BJ$53+BM6+((C6+E6+H6+K6+N6+Q6+T6+W6+Z6+AC6+AF6+AI6+AL6+AO6+AR6+AU6+AX6+BA6+BD6+BG6+BJ6)/(C$48+E$48+H$48+K$48+N$48+Q$48+T$48+W$48+Z$48+AC$48+AF$48+AI$48+AL$48+AO$48+AR$48+AU$48+AX$48+BA$48+BD$48+BG$48+BJ$48))*BJ$54) -> 356262.3 | BO6: =(BN6/BN$48)*BM$53 -> 0 | BP6: =epargne_mensuelle!AA6 -> 0 | BQ6: =IF(BN$48=0,BN6+BP6+((F6+H6+K6+N6+Q6+T6+W6+Z6+AC6+AF6+AI6+AL6+AO6+AR6+AU6+AX6+BA6+BD6+BG6+BJ6+BM6)/(F$48+H$48+K$48+N$48+Q$48+T$48+W$48+Z$48+AC$48+AF$48+AI$48+AL$48+AO$48+AR$48+AU$48+AX$48+BA$48+BD$48+BG$48+BJ$48+BM$48))*BM$54,BN6-((BN6/BN$48)*BM$52)+(BN6/BN$48)*BM$53+BP6+((F6+H6+K6+N6+Q6+T6+W6+Z6+AC6+AF6+AI6+AL6+AO6+AR6+AU6+AX6+BA6+BD6+BG6+BJ6+BM6)/(F$48+H$48+K$48+N$48+Q$48+T$48+W$48+Z$48+AC$48+AF$48+AI$48+AL$48+AO$48+AR$48+AU$48+AX$48+BA$48+BD$48+BG$48+BJ$48+BM$48))*BM$54) -> 356262.3 | BR6: =(BQ6/BQ$48)*BP$53 -> 0 | BS6: =epargne_mensuelle!AB6 -> 0 | BT6: =IF(BQ$48=0,BQ6+BS6+((I6+K6+N6+Q6+T6+W6+Z6+AC6+AF6+AI6+AL6+AO6+AR6+AU6+AX6+BA6+BD6+BG6+BJ6+BM6+BP6)/(I$48+K$48+N$48+Q$48+T$48+W$48+Z$48+AC$48+AF$48+AI$48+AL$48+AO$48+AR$48+AU$48+AX$48+BA$48+BD$48+BG$48+BJ$48+BM$48+BP$48))*BP$54,BQ6-((BQ6/BQ$48)*BP$52)+(BQ6/BQ$48)*BP$53+BS6+((I6+K6+N6+Q6+T6+W6+Z6+AC6+AF6+AI6+AL6+AO6+AR6+AU6+AX6+BA6+BD6+BG6+BJ6+BM6+BP6)/(I$48+K$48+N$48+Q$48+T$48+W$48+Z$48+AC$48+AF$48+AI$48+AL$48+AO$48+AR$48+AU$48+AX$48+BA$48+BD$48+BG$48+BJ$48+BM$48+BP$48))*BP$54) -> 356262.3 | BU6: =(BT6/BT$48)*BS$53 -> 0 | BV6: =cumul_epargne!C6 -> 1393753.8 | BW6: =D6+G6+J6+M6+P6+S6+V6+Y6+AB6+AE6+AH6+AK6+AN6+AQ6+AT6+AW6+AZ6+BC6+BF6+BI6+BL6+BO6+BR6+BU6 -> 232190.09 | BX6: =IF(BV6="",BW6,BV6+BW6) -> 1625943.9 | BZ6: =BX6+BY6 -> 1625943.9 | CA6: =IF(BV6="","",BW6/BV6) -> 0.16659333 | CB6: =BZ6/BZ$48 -> 0.035839949 | CC6: =CB6*(C$50-BW$58-BW$57) -> 155144.08 | CD6: =B6 -> ACTIONNIRE5
