Workbook

Sheet Fournitures par classe
A1: Pays | B1: Système | C1: Niveau | D1: Classe | E1: Catégorie | F1: Article | G1: Quantité | H1: Spécification | I1: Article canonique | J1: Clé | K1: Prix Standard (XAF) | L1: Prix Haut de Gamme (XAF) | M1: Sous-total Standard | N1: Sous-total Haut de Gamme
A2: Cameroun | B2: francophone | C2: Primaire | D2: SIL | E2: Cahier | F2: Paquet cahiers bananier 24 cahiers | G2: 1 | H2: doubles lignes | I2: Paquet cahiers bananier 24 cahiers | J2: =E2&"|"&I2&"|"&H2 | K2: =IFERROR(VLOOKUP(J2,'Articles uniques'!A:H,7,FALSE),"") | L2: =IFERROR(VLOOKUP(J2,'Articles uniques'!A:H,8,FALSE),"") | M2: =IF(ISNUMBER(K2),G2*K2,"") | N2: =IF(ISNUMBER(L2),G2*L2,"")
A3: Cameroun | B3: francophone | C3: Primaire | D3: SIL | E3: Cahier | F3: Cahier dessin petit format | G3: 1 | I3: Cahier dessin petit format | J3: =E3&"|"&I3&"|"&H3 | K3: =IFERROR(VLOOKUP(J3,'Articles uniques'!A:H,7,FALSE),"") | L3: =IFERROR(VLOOKUP(J3,'Articles uniques'!A:H,8,FALSE),"") | M3: =IF(ISNUMBER(K3),G3*K3,"") | N3: =IF(ISNUMBER(L3),G3*L3,"")
A4: Cameroun | B4: francophone | C4: Primaire | D4: SIL | E4: Cahier | F4: Cahier 60 leaves plain lines (English) | G4: 2 | I4: Cahier 60 leaves plain lines | J4: =E4&"|"&I4&"|"&H4 | K4: =IFERROR(VLOOKUP(J4,'Articles uniques'!A:H,7,FALSE),"") | L4: =IFERROR(VLOOKUP(J4,'Articles uniques'!A:H,8,FALSE),"") | M4: =IF(ISNUMBER(K4),G4*K4,"") | N4: =IF(ISNUMBER(L4),G4*L4,"")
A5: Cameroun | B5: francophone | C5: Primaire | D5: SIL | E5: Cahier | F5: Cahier de texte pour devoir à domicile | G5: 1 | I5: Cahier de texte pour devoir à domicile | J5: =E5&"|"&I5&"|"&H5 | K5: =IFERROR(VLOOKUP(J5,'Articles uniques'!A:H,7,FALSE),"") | L5: =IFERROR(VLOOKUP(J5,'Articles uniques'!A:H,8,FALSE),"") | M5: =IF(ISNUMBER(K5),G5*K5,"") | N5: =IF(ISNUMBER(L5),G5*L5,"")
A6: Cameroun | B6: francophone | C6: Primaire | D6: SIL | E6: Écriture | F6: Paquet crayons ordinaires 2B ou HB | G6: 2 | I6: Paquet crayons ordinaires 2B ou HB | J6: =E6&"|"&I6&"|"&H6 | K6: =IFERROR(VLOOKUP(J6,'Articles uniques'!A:H,7,FALSE),"") | L6: =IFERROR(VLOOKUP(J6,'Articles uniques'!A:H,8,FALSE),"") | M6: =IF(ISNUMBER(K6),G6*K6,"") | N6: =IF(ISNUMBER(L6),G6*L6,"")
A7: Cameroun | B7: francophone | C7: Primaire | D7: SIL | E7: Écriture | F7: Taille-crayon | G7: 2 | I7: Taille-crayon | J7: =E7&"|"&I7&"|"&H7 | K7: =IFERROR(VLOOKUP(J7,'Articles uniques'!A:H,7,FALSE),"") | L7: =IFERROR(VLOOKUP(J7,'Articles uniques'!A:H,8,FALSE),"") | M7: =IF(ISNUMBER(K7),G7*K7,"") | N7: =IF(ISNUMBER(L7),G7*L7,"")
A8: Cameroun | B8: francophone | C8: Primaire | D8: SIL | E8: Écriture | F8: Gomme | G8: 10 | H8: blanche | I8: Gomme | J8: =E8&"|"&I8&"|"&H8 | K8: =IFERROR(VLOOKUP(J8,'Articles uniques'!A:H,7,FALSE),"") | L8: =IFERROR(VLOOKUP(J8,'Articles uniques'!A:H,8,FALSE),"") | M8: =IF(ISNUMBER(K8),G8*K8,"") | N8: =IF(ISNUMBER(L8),G8*L8,"")
A9: Cameroun | B9: francophone | C9: Primaire | D9: SIL | E9: Écriture | F9: Tube de colle UHU | G9: 1 | I9: Tube de colle UHU | J9: =E9&"|"&I9&"|"&H9 | K9: =IFERROR(VLOOKUP(J9,'Articles uniques'!A:H,7,FALSE),"") | L9: =IFERROR(VLOOKUP(J9,'Articles uniques'!A:H,8,FALSE),"") | M9: =IF(ISNUMBER(K9),G9*K9,"") | N9: =IF(ISNUMBER(L9),G9*L9,"")
A10: Cameroun | B10: francophone | C10: Primaire | D10: SIL | E10: Écriture | F10: Paquet marqueurs Bic Velleda pour ardoise | G10: 1 | I10: Paquet marqueurs Bic Velleda pour ardoise | J10: =E10&"|"&I10&"|"&H10 | K10: =IFERROR(VLOOKUP(J10,'Articles uniques'!A:H,7,FALSE),"") | L10: =IFERROR(VLOOKUP(J10,'Articles uniques'!A:H,8,FALSE),"") | M10: =IF(ISNUMBER(K10),G10*K10,"") | N10: =IF(ISNUMBER(L10),G10*L10,"")
A11: Cameroun | B11: francophone | C11: Primaire | D11: SIL | E11: Écriture | F11: Paquet crayons couleur | G11: 1 | I11: Paquet crayons couleur | J11: =E11&"|"&I11&"|"&H11 | K11: =IFERROR(VLOOKUP(J11,'Articles uniques'!A:H,7,FALSE),"") | L11: =IFERROR(VLOOKUP(J11,'Articles uniques'!A:H,8,FALSE),"") | M11: =IF(ISNUMBER(K11),G11*K11,"") | N11: =IF(ISNUMBER(L11),G11*L11,"")
A12: Cameroun | B12: francophone | C12: Primaire | D12: SIL | E12: Ardoise | F12: Ardoise à feutre | G12: 1 | I12: Ardoise à feutre | J12: =E12&"|"&I12&"|"&H12 | K12: =IFERROR(VLOOKUP(J12,'Articles uniques'!A:H,7,FALSE),"") | L12: =IFERROR(VLOOKUP(J12,'Articles uniques'!A:H,8,FALSE),"") | M12: =IF(ISNUMBER(K12),G12*K12,"") | N12: =IF(ISNUMBER(L12),G12*L12,"")
A13: Cameroun | B13: francophone | C13: Primaire | D13: SIL | E13: Ardoise | F13: Effaçoir pour ardoise | G13: 2 | I13: Effaçoir pour ardoise | J13: =E13&"|"&I13&"|"&H13 | K13: =IFERROR(VLOOKUP(J13,'Articles uniques'!A:H,7,FALSE),"") | L13: =IFERROR(VLOOKUP(J13,'Articles uniques'!A:H,8,FALSE),"") | M13: =IF(ISNUMBER(K13),G13*K13,"") | N13: =IF(ISNUMBER(L13),G13*L13,"")
A14: Cameroun | B14: francophone | C14: Primaire | D14: SIL | E14: Géométrie | F14: Règle graduée 30cm | G14: 1 | I14: Règle graduée 30cm | J14: =E14&"|"&I14&"|"&H14 | K14: =IFERROR(VLOOKUP(J14,'Articles uniques'!A:H,7,FALSE),"") | L14: =IFERROR(VLOOKUP(J14,'Articles uniques'!A:H,8,FALSE),"") | M14: =IF(ISNUMBER(K14),G14*K14,"") | N14: =IF(ISNUMBER(L14),G14*L14,"")
A15: Cameroun | B15: francophone | C15: Primaire | D15: SIL | E15: Rangement | F15: Trousse | G15: 1 | I15: Trousse | J15: =E15&"|"&I15&"|"&H15 | K15: =IFERROR(VLOOKUP(J15,'Articles uniques'!A:H,7,FALSE),"") | L15: =IFERROR(VLOOKUP(J15,'Articles uniques'!A:H,8,FALSE),"") | M15: =IF(ISNUMBER(K15),G15*K15,"") | N15: =IF(ISNUMBER(L15),G15*L15,"")
A16: Cameroun | B16: francophone | C16: Primaire | D16: SIL | E16: Rangement | F16: Chemise à rabat | G16: 1 | I16: Chemise à rabat | J16: =E16&"|"&I16&"|"&H16 | K16: =IFERROR(VLOOKUP(J16,'Articles uniques'!A:H,7,FALSE),"") | L16: =IFERROR(VLOOKUP(J16,'Articles uniques'!A:H,8,FALSE),"") | M16: =IF(ISNUMBER(K16),G16*K16,"") | N16: =IF(ISNUMBER(L16),G16*L16,"")
A17: Cameroun | B17: francophone | C17: Primaire | D17: SIL | E17: Protection | F17: Couverture pour cahier | G17: 24 | H17: 6 bleues, 6 rouges, 6 jaunes, 6 vertes | I17: Couverture pour cahier | J17: =E17&"|"&I17&"|"&H17 | K17: =IFERROR(VLOOKUP(J17,'Articles uniques'!A:H,7,FALSE),"") | L17: =IFERROR(VLOOKUP(J17,'Articles uniques'!A:H,8,FALSE),"") | M17: =IF(ISNUMBER(K17),G17*K17,"") | N17: =IF(ISNUMBER(L17),G17*L17,"")
A18: Cameroun | B18: francophone | C18: Primaire | D18: SIL | E18: Papier | F18: Paquet papier canson | G18: 1 | I18: Paquet papier canson | J18: =E18&"|"&I18&"|"&H18 | K18: =IFERROR(VLOOKUP(J18,'Articles uniques'!A:H,7,FALSE),"") | L18: =IFERROR(VLOOKUP(J18,'Articles uniques'!A:H,8,FALSE),"") | M18: =IF(ISNUMBER(K18),G18*K18,"") | N18: =IF(ISNUMBER(L18),G18*L18,"")
A19: Cameroun | B19: francophone | C19: Primaire | D19: CP | E19: Cahier | F19: Cahier ordinaire 200 pages | G19: 2 | I19: Cahier ordinaire 200 pages | J19: =E19&"|"&I19&"|"&H19 | K19: =IFERROR(VLOOKUP(J19,'Articles uniques'!A:H,7,FALSE),"") | L19: =IFERROR(VLOOKUP(J19,'Articles uniques'!A:H,8,FALSE),"") | M19: =IF(ISNUMBER(K19),G19*K19,"") | N19: =IF(ISNUMBER(L19),G19*L19,"")
A20: Cameroun | B20: francophone | C20: Primaire | D20: CP | E20: Cahier | F20: Cahier 144 pages | G20: 6 | I20: Cahier 144 pages | J20: =E20&"|"&I20&"|"&H20 | K20: =IFERROR(VLOOKUP(J20,'Articles uniques'!A:H,7,FALSE),"") | L20: =IFERROR(VLOOKUP(J20,'Articles uniques'!A:H,8,FALSE),"") | M20: =IF(ISNUMBER(K20),G20*K20,"") | N20: =IF(ISNUMBER(L20),G20*L20,"")
A21: Cameroun | B21: francophone | C21: Primaire | D21: CP | E21: Cahier | F21: Cahier 80 leaves plain lines (English) | G21: 3 | I21: Cahier 80 leaves plain lines | J21: =E21&"|"&I21&"|"&H21 | K21: =IFERROR(VLOOKUP(J21,'Articles uniques'!A:H,7,FALSE),"") | L21: =IFERROR(VLOOKUP(J21,'Articles uniques'!A:H,8,FALSE),"") | M21: =IF(ISNUMBER(K21),G21*K21,"") | N21: =IF(ISNUMBER(L21),G21*L21,"")
A22: Cameroun | B22: francophone | C22: Primaire | D22: CP | E22: Cahier | F22: Cahier 40 leaves red and blue lines | G22: 1 | I22: Cahier 40 leaves red and blue lines | J22: =E22&"|"&I22&"|"&H22 | K22: =IFERROR(VLOOKUP(J22,'Articles uniques'!A:H,7,FALSE),"") | L22: =IFERROR(VLOOKUP(J22,'Articles uniques'!A:H,8,FALSE),"") | M22: =IF(ISNUMBER(K22),G22*K22,"") | N22: =IF(ISNUMBER(L22),G22*L22,"")
A23: Cameroun | B23: francophone | C23: Primaire | D23: CP | E23: Cahier | F23: Cahier doubles lignes bananier | G23: 15 | I23: Cahier doubles lignes bananier | J23: =E23&"|"&I23&"|"&H23 | K23: =IFERROR(VLOOKUP(J23,'Articles uniques'!A:H,7,FALSE),"") | L23: =IFERROR(VLOOKUP(J23,'Articles uniques'!A:H,8,FALSE),"") | M23: =IF(ISNUMBER(K23),G23*K23,"") | N23: =IF(ISNUMBER(L23),G23*L23,"")
A24: Cameroun | B24: francophone | C24: Primaire | D24: CP | E24: Cahier | F24: Cahier dessin petit format | G24: 1 | I24: Cahier dessin petit format | J24: =E24&"|"&I24&"|"&H24 | K24: =IFERROR(VLOOKUP(J24,'Articles uniques'!A:H,7,FALSE),"") | L24: =IFERROR(VLOOKUP(J24,'Articles uniques'!A:H,8,FALSE),"") | M24: =IF(ISNUMBER(K24),G24*K24,"") | N24: =IF(ISNUMBER(L24),G24*L24,"")
A25: Cameroun | B25: francophone | C25: Primaire | D25: CP | E25: Cahier | F25: Cahier de texte | G25: 1 | H25: pour devoir à domicile | I25: Cahier de texte | J25: =E25&"|"&I25&"|"&H25 | K25: =IFERROR(VLOOKUP(J25,'Articles uniques'!A:H,7,FALSE),"") | L25: =IFERROR(VLOOKUP(J25,'Articles uniques'!A:H,8,FALSE),"") | M25: =IF(ISNUMBER(K25),G25*K25,"") | N25: =IF(ISNUMBER(L25),G25*L25,"")
A26: Cameroun | B26: francophone | C26: Primaire | D26: CP | E26: Cahier | F26: Cahier de liaison | G26: 1 | I26: Cahier de liaison | J26: =E26&"|"&I26&"|"&H26 | K26: =IFERROR(VLOOKUP(J26,'Articles uniques'!A:H,7,FALSE),"") | L26: =IFERROR(VLOOKUP(J26,'Articles uniques'!A:H,8,FALSE),"") | M26: =IF(ISNUMBER(K26),G26*K26,"") | N26: =IF(ISNUMBER(L26),G26*L26,"")
A27: Cameroun | B27: francophone | C27: Primaire | D27: CP | E27: Écriture | F27: Stylo bleu | G27: 6 | I27: Stylo bleu | J27: =E27&"|"&I27&"|"&H27 | K27: =IFERROR(VLOOKUP(J27,'Articles uniques'!A:H,7,FALSE),"") | L27: =IFERROR(VLOOKUP(J27,'Articles uniques'!A:H,8,FALSE),"") | M27: =IF(ISNUMBER(K27),G27*K27,"") | N27: =IF(ISNUMBER(L27),G27*L27,"")
A28: Cameroun | B28: francophone | C28: Primaire | D28: CP | E28: Écriture | F28: Stylo rouge | G28: 4 | I28: Stylo rouge | J28: =E28&"|"&I28&"|"&H28 | K28: =IFERROR(VLOOKUP(J28,'Articles uniques'!A:H,7,FALSE),"") | L28: =IFERROR(VLOOKUP(J28,'Articles uniques'!A:H,8,FALSE),"") | M28: =IF(ISNUMBER(K28),G28*K28,"") | N28: =IF(ISNUMBER(L28),G28*L28,"")
A29: Cameroun | B29: francophone | C29: Primaire | D29: CP | E29: Écriture | F29: Paquet crayons HB ou 2B | G29: 1 | I29: Paquet crayons HB ou 2B | J29: =E29&"|"&I29&"|"&H29 | K29: =IFERROR(VLOOKUP(J29,'Articles uniques'!A:H,7,FALSE),"") | L29: =IFERROR(VLOOKUP(J29,'Articles uniques'!A:H,8,FALSE),"") | M29: =IF(ISNUMBER(K29),G29*K29,"") | N29: =IF(ISNUMBER(L29),G29*L29,"")
A30: Cameroun | B30: francophone | C30: Primaire | D30: CP | E30: Écriture | F30: Paquet crayons couleur | G30: 1 | I30: Paquet crayons couleur | J30: =E30&"|"&I30&"|"&H30 | K30: =IFERROR(VLOOKUP(J30,'Articles uniques'!A:H,7,FALSE),"") | L30: =IFERROR(VLOOKUP(J30,'Articles uniques'!A:H,8,FALSE),"") | M30: =IF(ISNUMBER(K30),G30*K30,"") | N30: =IF(ISNUMBER(L30),G30*L30,"")
A31: Cameroun | B31: francophone | C31: Primaire | D31: CP | E31: Écriture | F31: Taille-crayon | G31: 1 | I31: Taille-crayon | J31: =E31&"|"&I31&"|"&H31 | K31: =IFERROR(VLOOKUP(J31,'Articles uniques'!A:H,7,FALSE),"") | L31: =IFERROR(VLOOKUP(J31,'Articles uniques'!A:H,8,FALSE),"") | M31: =IF(ISNUMBER(K31),G31*K31,"") | N31: =IF(ISNUMBER(L31),G31*L31,"")
A32: Cameroun | B32: francophone | C32: Primaire | D32: CP | E32: Écriture | F32: Gomme | G32: 5 | I32: Gomme | J32: =E32&"|"&I32&"|"&H32 | K32: =IFERROR(VLOOKUP(J32,'Articles uniques'!A:H,7,FALSE),"") | L32: =IFERROR(VLOOKUP(J32,'Articles uniques'!A:H,8,FALSE),"") | M32: =IF(ISNUMBER(K32),G32*K32,"") | N32: =IF(ISNUMBER(L32),G32*L32,"")
A33: Cameroun | B33: francophone | C33: Primaire | D33: CP | E33: Écriture | F33: Colle UHU | G33: 1 | I33: Colle UHU | J33: =E33&"|"&I33&"|"&H33 | K33: =IFERROR(VLOOKUP(J33,'Articles uniques'!A:H,7,FALSE),"") | L33: =IFERROR(VLOOKUP(J33,'Articles uniques'!A:H,8,FALSE),"") | M33: =IF(ISNUMBER(K33),G33*K33,"") | N33: =IF(ISNUMBER(L33),G33*L33,"")
A34: Cameroun | B34: francophone | C34: Primaire | D34: CP | E34: Écriture | F34: Paquet marqueurs Bic Velleda + crayons couleur | G34: 1 | I34: Paquet marqueurs Bic Velleda + crayons couleur | J34: =E34&"|"&I34&"|"&H34 | K34: =IFERROR(VLOOKUP(J34,'Articles uniques'!A:H,7,FALSE),"") | L34: =IFERROR(VLOOKUP(J34,'Articles uniques'!A:H,8,FALSE),"") | M34: =IF(ISNUMBER(K34),G34*K34,"") | N34: =IF(ISNUMBER(L34),G34*L34,"")
A35: Cameroun | B35: francophone | C35: Primaire | D35: CP | E35: Ardoise | F35: Ardoise à feutre | G35: 1 | I35: Ardoise à feutre | J35: =E35&"|"&I35&"|"&H35 | K35: =IFERROR(VLOOKUP(J35,'Articles uniques'!A:H,7,FALSE),"") | L35: =IFERROR(VLOOKUP(J35,'Articles uniques'!A:H,8,FALSE),"") | M35: =IF(ISNUMBER(K35),G35*K35,"") | N35: =IF(ISNUMBER(L35),G35*L35,"")
A36: Cameroun | B36: francophone | C36: Primaire | D36: CP | E36: Ardoise | F36: Effaçoir pour ardoise | G36: 1 | I36: Effaçoir pour ardoise | J36: =E36&"|"&I36&"|"&H36 | K36: =IFERROR(VLOOKUP(J36,'Articles uniques'!A:H,7,FALSE),"") | L36: =IFERROR(VLOOKUP(J36,'Articles uniques'!A:H,8,FALSE),"") | M36: =IF(ISNUMBER(K36),G36*K36,"") | N36: =IF(ISNUMBER(L36),G36*L36,"")
A37: Cameroun | B37: francophone | C37: Primaire | D37: CP | E37: Géométrie | F37: Règle graduée 30cm | G37: 1 | I37: Règle graduée 30cm | J37: =E37&"|"&I37&"|"&H37 | K37: =IFERROR(VLOOKUP(J37,'Articles uniques'!A:H,7,FALSE),"") | L37: =IFERROR(VLOOKUP(J37,'Articles uniques'!A:H,8,FALSE),"") | M37: =IF(ISNUMBER(K37),G37*K37,"") | N37: =IF(ISNUMBER(L37),G37*L37,"")
... A39: Cameroun | B39: francophone | C39: Primaire | D39: CP | E39: Rangement | F39: Chemise à rabat | G39: 1 | I39: Chemise à rabat | J39: =E39&"|"&I39&"|"&H39 | K39: =IFERROR(VLOOKUP(J39,'Articles uniques'!A:H,7,FALSE),"") | L39: =IFERROR(VLOOKUP(J39,'Articles uniques'!A:H,8,FALSE),"") | M39: =IF(ISNUMBER(K39),G39*K39,"") | N39: =IF(ISNUMBER(L39),G39*L39,"")
A40: Cameroun | B40: francophone | C40: Primaire | D40: CP | E40: Protection | F40: Couverture pour cahier | G40: 20 | H40: 5 bleues, 5 rouges, 5 jaunes, 5 vertes | I40: Couverture pour cahier | J40: =E40&"|"&I40&"|"&H40 | K40: =IFERROR(VLOOKUP(J40,'Articles uniques'!A:H,7,FALSE),"") | L40: =IFERROR(VLOOKUP(J40,'Articles uniques'!A:H,8,FALSE),"") | M40: =IF(ISNUMBER(K40),G40*K40,"") | N40: =IF(ISNUMBER(L40),G40*L40,"")
A41: Cameroun | B41: francophone | C41: Primaire | D41: CP | E41: Protection | F41: Couvre-livre | G41: 1 | H41: paquet | I41: Couvre-livre | J41: =E41&"|"&I41&"|"&H41 | K41: =IFERROR(VLOOKUP(J41,'Articles uniques'!A:H,7,FALSE),"") | L41: =IFERROR(VLOOKUP(J41,'Articles uniques'!A:H,8,FALSE),"") | M41: =IF(ISNUMBER(K41),G41*K41,"") | N41: =IF(ISNUMBER(L41),G41*L41,"")
...

Sheet Résumé par classe
A1: Classe | B1: Pays | C1: Système | D1: Niveau | E1: Nb articles distincts | F1: Qté totale
A2: SIL | B2: Cameroun | C2: francophone | D2: Primaire | E2: 17 | F2: 53
A3: CP | B3: Cameroun | C3: francophone | D3: Primaire | E3: 23 | F3: 76
A4: CE1 | B4: Cameroun | C4: francophone | D4: Primaire | E4: 28 | F4: 43
A5: CE2 | B5: Cameroun | C5: francophone | D5: Primaire | E5: 27 | F5: 42
A6: CM1 | B6: Cameroun | C6: francophone | D6: Primaire | E6: 29 | F6: 32
A7: CM2 | B7: Cameroun | C7: francophone | D7: Primaire | E7: 30 | F7: 34
A8: SIL BIL | B8: Cameroun | C8: bilingue | D8: Primaire | E8: 28 | F8: 96
A9: CP BIL | B9: Cameroun | C9: bilingue | D9: Primaire | E9: 32 | F9: 114
A10: CE1 BIL | B10: Cameroun | C10: bilingue | D10: Primaire | E10: 31 | F10: 63
A11: CE2 BIL | B11: Cameroun | C11: bilingue | D11: Primaire | E11: 31 | F11: 62
A12: CM1 BIL | B12: Cameroun | C12: bilingue | D12: Primaire | E12: 9 | F12: 49
A13: Class 1 | B13: Cameroun | C13: anglophone | D13: Primaire | E13: 29 | F13: 84
... A33: Upper Sixth | B33: Cameroun | C33: anglophone | D33: Secondaire | E33: 28 | F33: 33

Sheet Articles uniques
A1: Clé (ne pas modifier) | B1: Catégorie | C1: Article (canonique) | D1: Spécification / Couleur | E1: Matières / Variantes (info) | F1: Qté totale (toutes classes) | G1: Prix Standard (XAF) | H1: Prix Haut de Gamme (XAF)
A2: Ardoise|Ardoise à feutre| | B2: Ardoise | C2: Ardoise à feutre | F2: 8
A3: Ardoise|Ardoise à marqueurs| | B3: Ardoise | C3: Ardoise à marqueurs | F3: 2
A4: Ardoise|Duster| | B4: Ardoise | C4: Duster | F4: 6
A5: Ardoise|Effaçoir| | B5: Ardoise | C5: Effaçoir | F5: 6
A6: Ardoise|Effaçoir / Duster| | B6: Ardoise | C6: Effaçoir / Duster | F6: 2
A7: Ardoise|Effaçoir pour ardoise| | B7: Ardoise | C7: Effaçoir pour ardoise | F7: 3
A8: Ardoise|Paquet feutres pour ardoise| | B8: Ardoise | C8: Paquet feutres pour ardoise | F8: 2
A9: Ardoise|White board| | B9: Ardoise | C9: White board | F9: 6
A10: Ardoise|White tablet| | B10: Ardoise | C10: White tablet | F10: 1
A11: Cahier|200 pages ledger| | B11: Cahier | C11: 200 pages ledger | E11: Food and Nutrition | F11: 1
A12: Cahier|300 pages ledger| | B12: Cahier | C12: 300 pages ledger | E12: Computer Science | F12: 4
A13: Cahier|Book 20 leaves plain lines| | B13: Cahier | C13: Book 20 leaves plain lines | E13: Music, Sports | F13: 4
A14: Cahier|Book 20 leaves red and blue lines| | B14: Cahier | C14: Book 20 leaves red and blue lines | E14: Writing | F14: 2
A15: Cahier|Book 200 leaves ledger plain lines| | B15: Cahier | C15: Book 200 leaves ledger plain lines | E15: English | F15: 4
A16: Cahier|Book 200 leaves ledger square lines| | B16: Cahier | C16: Book 200 leaves ledger square lines | E16: Maths | F16: 4
A17: Cahier|Book 40 leaves plain lines| | B17: Cahier | C17: Book 40 leaves plain lines | E17: ICT/NLC | F17: 2
A18: Cahier|Book 40 leaves plain lines|Civics, NLC, Human R, Agro Past, Arts, Moral Ed, Music | B18: Cahier | C18: Book 40 leaves plain lines | D18: Civics, NLC, Human R, Agro Past, Arts, Moral Ed, Music | E18: matières mineures | F18: 8
A19: Cahier|Book 40 leaves plain lines|Human Right, Moral Ed, visual Arts, NLC | B19: Cahier | C19: Book 40 leaves plain lines | D19: Human Right, Moral Ed, visual Arts, NLC | F19: 5
A20: Cahier|Book 40 leaves plain lines|Human Rights, Moral Ed, NLC, Sports, SWB | B20: Cahier | C20: Book 40 leaves plain lines | D20: Human Rights, Moral Ed, NLC, Sports, SWB | E20: matières mineures | F20: 5
A21: Cahier|Book 40 leaves plain lines|Moral Ed, Human Rights, Arts & Craft | B21: Cahier | C21: Book 40 leaves plain lines | D21: Moral Ed, Human Rights, Arts & Craft | F21: 3
A22: Cahier|Book 60 leaves plain lines| | B22: Cahier | C22: Book 60 leaves plain lines | E22: ICT/NLC, S/S | F22: 6
A23: Cahier|Book 60 leaves plain lines|Civics, Agro Pastoral, Arts, SWB, Music, Sports | B23: Cahier | C23: Book 60 leaves plain lines | D23: Civics, Agro Pastoral, Arts, SWB, Music, Sports | E23: matières mineures | F23: 6
A24: Cahier|Book 60 leaves plain lines|Health, Environmental, ICT, Home Ec, Civics, Tech, Music, Agro-Past, Arts | B24: Cahier | C24: Book 60 leaves plain lines | D24: Health, Environmental, ICT, Home Ec, Civics, Tech, Music, Agro-Past, Arts | E24: matières majeures | F24: 9
A25: Cahier|Book 60 leaves plain lines|Home Ec, Agro Pastoral, Civics, Sports, Music, NLC | B25: Cahier | C25: Book 60 leaves plain lines | D25: Home Ec, Agro Pastoral, Civics, Sports, Music, NLC | E25: matières mineures | F25: 6
A26: Cahier|Book 60 leaves plain lines|S/W building, Health, Environmental, Tech, ICT, History, Geography, Home Ec, Peace | B26: Cahier | C26: Book 60 leaves plain lines | D26: S/W building, Health, Environmental, Tech, ICT, History, Geography, Home Ec, Peace | E26: matières majeures | F26: 10
A27: Cahier|Book 80 leaves plain lines| | B27: Cahier | C27: Book 80 leaves plain lines | E27: Eng/SWB, English, History, Geography, Eval, SWB, English/Evaluation, English/SWB, Home work, S/T, Sc/Tech, V/S | F27: 24
A28: Cahier|Book 80 leaves plain lines|Eval, Health, Environmental, SWB, History, Geography, ICT, Dictation, Tech | B28: Cahier | C28: Book 80 leaves plain lines | D28: Eval, Health, Environmental, SWB, History, Geography, ICT, Dictation, Tech | E28: matières majeures | F28: 10
A29: Cahier|Book 80 leaves plain lines|History, Geography, Health, Dictation, Eval, Tech, ICT, Home Ec | B29: Cahier | C29: Book 80 leaves plain lines | D29: History, Geography, Health, Dictation, Eval, Tech, ICT, Home Ec | E29: matières majeures | F29: 10
A30: Cahier|Book 80 leaves square lines| | B30: Cahier | C30: Book 80 leaves square lines | E30: Maths | F30: 8
A31: Cahier|Book red and blue lines| | B31: Cahier | C31: Book red and blue lines | E31: writing | F31: 2
A32: Cahier|Cahier 100 pages| | B32: Cahier | C32: Cahier 100 pages | E32: Informatique, Informatique 1ère D, Mathématiques 1ère C, Mathématiques 2nde A4, TM | F32: 11
A33: Cahier|Cahier 120 pages| | B33: Cahier | C33: Cahier 120 pages | E33: Français, Langue française, Langue française + Littérature | F33: 13
A34: Cahier|Cahier 144 pages| | B34: Cahier | C34: Cahier 144 pages | E34: Sport | F34: 18
A35: Cahier|Cahier 144 pages petit format| | B35: Cahier | C35: Cahier 144 pages petit format | E35: Sport | F35: 1
A36: Cahier|Cahier 192 pages petit format| | B36: Cahier | C36: Cahier 192 pages petit format | E36: Espagnol | F36: 2
A37: Cahier|Cahier 20 leaves red and blue lines| | B37: Cahier | C37: Cahier 20 leaves red and blue lines | F37: 1
A38: Cahier|Cahier 200 leaves ledger plain lines| | B38: Cahier | C38: Cahier 200 leaves ledger plain lines | E38: English | F38: 2
A39: Cahier|Cahier 200 leaves ledger square lines| | B39: Cahier | C39: Cahier 200 leaves ledger square lines | E39: Maths | F39: 2
A40: Cahier|Cahier 200 pages| | B40: Cahier | C40: Cahier 200 pages | E40: Bureautique, Citoyenneté, Commerce, Communication professionnelle, Comptabilité financière, Maths/Stats appliquées, Mathématiques, Org. travail administratif, SVTEEHB, SVTEEHB 2nde C, Économie générale | F40: 24
...
